Workbook
Name NonLinePayTable: 'Step-9-AllRSNotWilds'!$A$13:$F$17
Name NumRows: 'Step-9-AllRSNotWilds'!$D$22
Name Paytable: 'Step-9-AllRSNotWilds'!$B$25:$D$35
Name Total: 'Step-9-AllRSNotWilds'!$A$18:$F$18

Sheet Step-1
A1: Symbol Set Population | B1: Symbol Set Population | C1: Symbol Set Population | D1: Symbol Set Population | E1: Symbol Set Population | F1: Symbol Set Population | I1: Prize | J1: R1 | K1: R2 | L1: R3 | M1: R4 | N1: R5 | O1: HITS | P1: Hit Rate | Q1: Total Hit Rate | R1: RTP(%) | S1: RTP(%) 1c | U1: Sim RTP | V1: Delta
A2: Symbol | B2: BaseRS11R0 | C2: BaseRS11R1 | D2: BaseRS11R2 | E2: BaseRS11R3 | F2: BaseRS11R4 | I2: 5xH1 | J2: =B3+B4 -> 2 | K2: =C3+C4 -> 1 | L2: =D3+D4 -> 35 | M2: =E3+E4 -> 32 | N2: =F3+F4 -> 3 | O2: =PRODUCT(J2:N2) -> 6720 | P2: =O2/$B$16 -> 5.6367244e-05 | Q2: =P2*$A$19 -> 0.0011273449 | R2: =Q2*B22 -> 0.084550866 | S2: =R2/$B$19 -> 0.0084550866 | U2: 0.0083604 | V2: =S2-U2 -> 9.468658e-05
A3: WD | B3: 0 | C3: 1 | D3: 29 | E3: 28 | F3: 0 | I3: 4xH1 | J3: =J2 -> 2 | K3: =K2 -> 1 | L3: =L2 -> 35 | M3: =M2 -> 32 | N3: =F15-N2 -> 45 | O3: =PRODUCT(J3:N3) -> 100800 | P3: =O3/$B$16 -> 0.00084550866 | Q3: =P3*$A$19 -> 0.016910173 | R3: =Q3*C22 -> 0.42275433 | S3: =R3/$B$19 -> 0.042275433 | U3: 0.041926025 | V3: =S3-U3 -> 0.0003494079
A4: H1 | B4: 2 | C4: 0 | D4: 6 | E4: 4 | F4: 3 | I4: 3xH1 | J4: =J2 -> 2 | K4: =K2 -> 1 | L4: =L2 -> 35 | M4: =E15-M2 -> 16 | N4: 48 | O4: =PRODUCT(J4:N4) -> 53760 | P4: =O4/$B$16 -> 0.00045093795 | Q4: =P4*$A$19 -> 0.009018759 | R4: =Q4*D22 -> 0.018037518 | S4: =R4/$B$19 -> 0.0018037518 | U4: 0.00178491 | V4: =S4-U4 -> 1.8841804e-05
A5: H2 | B5: 3 | C5: 0 | D5: 4 | E5: 4 | F5: 4 | I5: 5xH2 | J5: =B3+B5 -> 3 | K5: =C3+C5 -> 1 | L5: =D3+D5 -> 33 | M5: =E3+E5 -> 32 | N5: =F3+F5 -> 4 | O5: =PRODUCT(J5:N5) -> 12672 | P5: =O5/$B$16 -> 0.00010629252 | Q5: =P5*$A$19 -> 0.0021258503 | R5: =Q5*B23 -> 0.10629252 | S5: =R5/$B$19 -> 0.010629252 | U5: 0.0105633 | V5: =S5-U5 -> 6.5951701e-05
A6: H3 | B6: 3 | C6: 0 | D6: 0 | E6: 0 | F6: 6 | I6: 4xH2 | J6: =J5 -> 3 | K6: =K5 -> 1 | L6: =L5 -> 33 | M6: =M5 -> 32 | N6: =F15-N5 -> 44 | O6: =PRODUCT(J6:N6) -> 139392 | P6: =O6/$B$16 -> 0.0011692177 | Q6: =P6*$A$19 -> 0.023384354 | R6: =Q6*C23 -> 0.28061224 | S6: =R6/$B$19 -> 0.028061224 | U6: 0.027816048 | V6: =S6-U6 -> 0.00024517649
A7: H4 | B7: 2 | C7: 8 | D7: 2 | E7: 0 | F7: 6 | I7: 3xH2 | J7: =J5 -> 3 | K7: =K5 -> 1 | L7: =L5 -> 33 | M7: =D15-M5 -> 17 | N7: =F15 -> 48 | O7: =PRODUCT(J7:N7) -> 80784 | P7: =O7/$B$16 -> 0.0006776148 | Q7: =P7*$A$19 -> 0.013552296 | R7: =Q7*D23 -> 0.027104592 | S7: =R7/$B$19 -> 0.0027104592 | U7: 0.00253115 | V7: =S7-U7 -> 0.00017930918
A8: L1 | B8: 4 | C8: 8 | D8: 4 | E8: 6 | F8: 5 | I8: 5xH3 | J8: =B3+B6 -> 3 | K8: =C3+C6 -> 1 | L8: =D3+D6 -> 29 | M8: =E3+E6 -> 28 | N8: =F3+F6 -> 6 | O8: =PRODUCT(J8:N8) -> 14616 | P8: =O8/$B$16 -> 0.00012259876 | Q8: =P8*$A$19 -> 0.0024519751 | R8: =Q8*B24 -> 0.12259876 | S8: =R8/$B$19 -> 0.012259876 | U8: 0.01200955 | V8: =S8-U8 -> 0.00025032554
A9: L2 | B9: 7 | C9: 2 | D9: 2 | E9: 0 | F9: 6 | I9: 4xH3 | J9: =J8 -> 3 | K9: =K8 -> 1 | L9: =L8 -> 29 | M9: =M8 -> 28 | N9: =F15-N8 -> 42 | O9: =PRODUCT(J9:N9) -> 102312 | P9: =O9/$B$16 -> 0.00085819129 | Q9: =P9*$A$19 -> 0.017163826 | R9: =Q9*C24 -> 0.20596591 | S9: =R9/$B$19 -> 0.020596591 | U9: 0.020313048 | V9: =S9-U9 -> 0.00028354291
A10: L3 | B10: 7 | C10: 2 | D10: 2 | E10: 2 | F10: 6 | I10: 3xH3 | J10: =J9 -> 3 | K10: =K9 -> 1 | L10: =L9 -> 29 | M10: =E15-M9 -> 20 | N10: =F15 -> 48 | O10: =PRODUCT(J10:N10) -> 83520 | P10: =O10/$B$16 -> 0.00070056432 | Q10: =P10*$A$19 -> 0.014011286 | R10: =Q10*D24 -> 0.028022573 | S10: =R10/$B$19 -> 0.0028022573 | U10: 0.00276997 | V10: =S10-U10 -> 3.2287267e-05
A11: L4 | B11: 2 | C11: 6 | D11: 0 | E11: 0 | F11: 6 | I11: 5xH4 | J11: =B3+B7 -> 2 | K11: =C3+C7 -> 9 | L11: =D3+D7 -> 31 | M11: =E3+E7 -> 28 | N11: =F3+F7 -> 6 | O11: =PRODUCT(J11:N11) -> 93744 | P11: =O11/$B$16 -> 0.00078632305 | Q11: =P11*$A$19 -> 0.015726461 | R11: =Q11*B25 -> 0.78632305 | S11: =R11/$B$19 -> 0.078632305 | U11: 0.0776982 | V11: =S11-U11 -> 0.00093410519
A12: L5 | B12: 2 | C12: 6 | D12: 0 | E12: 4 | F12: 6 | I12: 4xH4 | J12: =J11 -> 2 | K12: =K11 -> 9 | L12: =L11 -> 31 | M12: =M11 -> 28 | N12: =F15-N11 -> 42 | O12: =PRODUCT(J12:N12) -> 656208 | P12: =O12/$B$16 -> 0.0055042614 | Q12: =P12*$A$19 -> 0.11008523 | R12: =Q12*C25 -> 1.3210227 | S12: =R12/$B$19 -> 0.13210227 | U12: 0.13058296 | V12: =S12-U12 -> 0.0015193167
A13: SC | B13: 0 | C13: 0 | D13: 0 | E13: 0 | F13: 0 | I13: 3xH4 | J13: =J12 -> 2 | K13: =K12 -> 9 | L13: =L12 -> 31 | M13: =E15-M11 -> 20 | N13: =F15 -> 48 | O13: =PRODUCT(J13:N13) -> 535680 | P13: =O13/$B$16 -> 0.0044932746 | Q13: =P13*$A$19 -> 0.089865492 | R13: =Q13*D25 -> 0.17973098 | S13: =R13/$B$19 -> 0.017973098 | U13: 0.017740398 | V13: =S13-U13 -> 0.00023270033
A14: RS | B14: 0 | C14: 0 | D14: 0 | E14: 0 | F14: 0 | I14: 5xL1 | J14: =B3+B8 -> 4 | K14: =C3+C8 -> 9 | L14: =D3+D8 -> 33 | M14: =E3+E8 -> 34 | N14: =F3+F8 -> 5 | O14: =PRODUCT(J14:N14) -> 201960 | P14: =O14/$B$16 -> 0.001694037 | Q14: =P14*$A$19 -> 0.03388074 | R14: =Q14*B26 -> 1.3552296 | S14: =R14/$B$19 -> 0.13552296 | U14: 0.134433 | V14: =S14-U14 -> 0.0010899592
A15: Total | B15: =SUM(B3:B14) -> 32 | C15: =SUM(C3:C14) -> 33 | D15: =SUM(D3:D14) -> 49 | E15: =SUM(E3:E14) -> 48 | F15: =SUM(F3:F14) -> 48 | I15: 4xL1 | J15: =J14 -> 4 | K15: =K14 -> 9 | L15: =L14 -> 33 | M15: =M14 -> 34 | N15: =F15-N14 -> 43 | O15: =PRODUCT(J15:N15) -> 1736856 | P15: =O15/$B$16 -> 0.014568718 | Q15: =P15*$A$19 -> 0.29137436 | R15: =Q15*C26 -> 2.0396205 | S15: =R15/$B$19 -> 0.20396205 | U15: 0.20189186 | V15: =S15-U15 -> 0.0020701956
A16: Total Cycles | B16: =PRODUCT(B15:F15) -> 119218176 | I16: 3xL1 | J16: =J14 -> 4 | K16: =K14 -> 9 | L16: =L14 -> 33 | M16: =E15-M14 -> 14 | N16: =F15 -> 48 | O16: =PRODUCT(J16:N16) -> 798336 | P16: =O16/$B$16 -> 0.0066964286 | Q16: =P16*$A$19 -> 0.13392857 | R16: =Q16*D26 -> 0.26785714 | S16: =R16/$B$19 -> 0.026785714 | U16: 0.026551312 | V16: =S16-U16 -> 0.00023440229
I17: 5xL2 | J17: =B3+B9 -> 7 | K17: =C3+C9 -> 3 | L17: =D3+D9 -> 31 | M17: =E3+E9 -> 28 | N17: =F3+F9 -> 6 | O17: =PRODUCT(J17:N17) -> 109368 | P17: =O17/$B$16 -> 0.00091737689 | Q17: =P17*$A$19 -> 0.018347538 | R17: =Q17*B27 -> 0.45868845 | S17: =R17/$B$19 -> 0.045868845 | U17: 0.045273475 | V17: =S17-U17 -> 0.0005953697
A18: Total Lines | B18: Wage | I18: 4xL2 | J18: =J17 -> 7 | K18: =K17 -> 3 | L18: =L17 -> 31 | M18: =M17 -> 28 | N18: =F15-N17 -> 42 | O18: =PRODUCT(J18:N18) -> 765576 | P18: =O18/$B$16 -> 0.0064216383 | Q18: =P18*$A$19 -> 0.12843277 | R18: =Q18*C27 -> 0.64216383 | S18: =R18/$B$19 -> 0.064216383 | U18: 0.063422615 | V18: =S18-U18 -> 0.00079376758
A19: 20 | B19: 10 | I19: 3xL2 | J19: =J17 -> 7 | K19: =K17 -> 3 | L19: =L17 -> 31 | M19: =E15-M17 -> 20 | N19: =F15 -> 48 | O19: =PRODUCT(J19:N19) -> 624960 | P19: =O19/$B$16 -> 0.0052421537 | Q19: =P19*$A$19 -> 0.10484307 | R19: =Q19*D27 -> 0.20968615 | S19: =R19/$B$19 -> 0.020968615 | U19: 0.02073553 | V19: =S19-U19 -> 0.00023308472
I20: 5xL3 | J20: =B3+B10 -> 7 | K20: =C3+C10 -> 3 | L20: =D3+D10 -> 31 | M20: =E3+E10 -> 30 | N20: =F3+F10 -> 6 | O20: =PRODUCT(J20:N20) -> 117180 | P20: =O20/$B$16 -> 0.00098290381 | Q20: =P20*$A$19 -> 0.019658076 | R20: =Q20*B28 -> 0.49145191 | S20: =R20/$B$19 -> 0.049145191 | U20: 0.048552025 | V20: =S20-U20 -> 0.00059316575
A21: Symbol | B21: 5 OAK | C21: 4 OAK | D21: 3 OAK | I21: 4xL3 | J21: =J20 -> 7 | K21: =K20 -> 3 | L21: =L20 -> 31 | M21: =M20 -> 30 | N21: =F15-N20 -> 42 | O21: =PRODUCT(J21:N21) -> 820260 | P21: =O21/$B$16 -> 0.0068803267 | Q21: =P21*$A$19 -> 0.13760653 | R21: =Q21*C28 -> 0.68803267 | S21: =R21/$B$19 -> 0.068803267 | U21: 0.067928595 | V21: =S21-U21 -> 0.00087467205
A22: H1 | B22: 75 | C22: 25 | D22: 2 | I22: 3xL3 | J22: =J20 -> 7 | K22: =K20 -> 3 | L22: =L20 -> 31 | M22: =E15-M20 -> 18 | N22: =F15 -> 48 | O22: =PRODUCT(J22:N22) -> 562464 | P22: =O22/$B$16 -> 0.0047179383 | Q22: =P22*$A$19 -> 0.094358766 | R22: =Q22*D28 -> 0.18871753 | S22: =R22/$B$19 -> 0.018871753 | U22: 0.018654278 | V22: =S22-U22 -> 0.00021747525
A23: H2 | B23: 50 | C23: 12 | D23: 2 | I23: 5xL4 | J23: =B3+B11 -> 2 | K23: =C3+C11 -> 7 | L23: =D3+D11 -> 29 | M23: =E3+E11 -> 28 | N23: =F3+F11 -> 6 | O23: =PRODUCT(J23:N23) -> 68208 | P23: =O23/$B$16 -> 0.00057212753 | Q23: =P23*$A$19 -> 0.011442551 | R23: =Q23*B29 -> 0.28606376 | S23: =R23/$B$19 -> 0.028606376 | U23: 0.0282177 | V23: =S23-U23 -> 0.00038867626
A24: H3 | B24: 50 | C24: 12 | D24: 2 | I24: 4xL4 | J24: =J23 -> 2 | K24: =K23 -> 7 | L24: =L23 -> 29 | M24: =M23 -> 28 | N24: =F15-N23 -> 42 | O24: =PRODUCT(J24:N24) -> 477456 | P24: =O24/$B$16 -> 0.0040048927 | Q24: =P24*$A$19 -> 0.080097854 | R24: =Q24*C29 -> 0.40048927 | S24: =R24/$B$19 -> 0.040048927 | U24: 0.03949486 | V24: =S24-U24 -> 0.00055406677
A25: H4 | B25: 50 | C25: 12 | D25: 2 | I25: 3xL4 | J25: =J23 -> 2 | K25: =K23 -> 7 | L25: =L23 -> 29 | M25: =E15-M23 -> 20 | N25: =F15 -> 48 | O25: =PRODUCT(J25:N25) -> 389760 | P25: =O25/$B$16 -> 0.0032693001 | Q25: =P25*$A$19 -> 0.065386003 | R25: =Q25*D29 -> 0.13077201 | S25: =R25/$B$19 -> 0.013077201 | U25: 0.012893874 | V25: =S25-U25 -> 0.00018332658
A26: L1 | B26: 40 | C26: 7 | D26: 2 | I26: 5xL5 | J26: =B3+B12 -> 2 | K26: =C3+C12 -> 7 | L26: =D3+D12 -> 29 | M26: =E3+E12 -> 32 | N26: =F3+F12 -> 6 | O26: =PRODUCT(J26:N26) -> 77952 | P26: =O26/$B$16 -> 0.00065386003 | Q26: =P26*$A$19 -> 0.013077201 | R26: =Q26*B30 -> 0.32693001 | S26: =R26/$B$19 -> 0.032693001 | U26: 0.032289325 | V26: =S26-U26 -> 0.00040367644
A27: L2 | B27: 25 | C27: 5 | D27: 2 | I27: 4xL5 | J27: =J26 -> 2 | K27: =K26 -> 7 | L27: =L26 -> 29 | M27: =M26 -> 32 | N27: =F15-N26 -> 42 | O27: =PRODUCT(J27:N27) -> 545664 | P27: =O27/$B$16 -> 0.0045770202 | Q27: =P27*$A$19 -> 0.091540404 | R27: =Q27*C30 -> 0.45770202 | S27: =R27/$B$19 -> 0.045770202 | U27: 0.04506687 | V27: =S27-U27 -> 0.00070333202
A28: L3 | B28: 25 | C28: 5 | D28: 2 | I28: 3xL5 | J28: =J26 -> 2 | K28: =K26 -> 7 | L28: =L26 -> 29 | M28: =E15-M26 -> 16 | N28: =F15 -> 48 | O28: =PRODUCT(J28:N28) -> 311808 | P28: =O28/$B$16 -> 0.0026154401 | Q28: =P28*$A$19 -> 0.052308802 | R28: =Q28*D30 -> 0.1046176 | S28: =R28/$B$19 -> 0.01046176 | U28: 0.010308826 | V28: =S28-U28 -> 0.00015293446
A29: L4 | B29: 25 | C29: 5 | D29: 2 | S29: =SUM(S2:S28) -> 1.1631039 | U29: =SUM(U2:U28) -> 1.1498101 | V29: =S29-U29 -> 0.013293756
A30: L5 | B30: 25 | C30: 5 | D30: 2

Sheet Step-2
A1: Symbol Set Population | B1: Symbol Set Population | C1: Symbol Set Population | D1: Symbol Set Population | E1: Symbol Set Population | F1: Symbol Set Population | I1: Prize | J1: R1 | K1: R2 | L1: R3 | M1: R4 | N1: R5 | O1: HITS | P1: Hit Rate | Q1: Total Hit Rate | R1: RTP(%) | S1: RTP(%) 1c | U1: Sim RTP | V1: Delta
A2: Symbol | B2: BaseRS11R0 | C2: BaseRS11R1 | D2: BaseRS11R2 | E2: BaseRS11R3 | F2: BaseRS11R4 | I2: 5xH1 | J2: =B3+B4 -> 2 | K2: =C3+C4 -> 1 | L2: =D3+D4 -> 9 | M2: =E3+E4 -> 32 | N2: =F3+F4 -> 3 | O2: =PRODUCT(J2:N2) -> 1728 | P2: =O2/$B$19 -> 2.7316434e-05 | Q2: =P2*$A$22 -> 0.00054632867 | R2: =Q2*B25 -> 0.04097465 | S2: =R2/$B$22 -> 0.004097465 | U2: 0.0041211 | V2: =S2-U2 -> -2.3634965e-05
A3: WD | B3: 0 | C3: 1 | D3: 3 | E3: 28 | F3: 0 | I3: 4xH1 | J3: =J2 -> 2 | K3: =K2 -> 1 | L3: =L2 -> 9 | M3: =M2 -> 32 | N3: =F18-N2 -> 45 | O3: =PRODUCT(J3:N3) -> 25920 | P3: =O3/$B$19 -> 0.0004097465 | Q3: =P3*$A$22 -> 0.0081949301 | R3: =Q3*C25 -> 0.20487325 | S3: =R3/$B$22 -> 0.020487325 | U3: 0.020463525 | V3: =S3-U3 -> 2.3800175e-05
A4: H1 | B4: 2 | C4: 0 | D4: 6 | E4: 4 | F4: 3 | I4: 3xH1 | J4: =J2 -> 2 | K4: =K2 -> 1 | L4: =L2 -> 9 | M4: =E18-M2 -> 16 | N4: 48 | O4: =PRODUCT(J4:N4) -> 13824 | P4: =O4/$B$19 -> 0.00021853147 | Q4: =P4*$A$22 -> 0.0043706294 | R4: =Q4*D25 -> 0.0087412587 | S4: =R4/$B$22 -> 0.00087412587 | U4: 0.000871696 | V4: =S4-U4 -> 2.4298741e-06
A5: H2 | B5: 3 | C5: 0 | D5: 4 | E5: 4 | F5: 4 | I5: 5xH2 | J5: =B3+B5 -> 3 | K5: =C3+C5 -> 1 | L5: =D3+D5 -> 7 | M5: =E3+E5 -> 32 | N5: =F3+F5 -> 4 | O5: =PRODUCT(J5:N5) -> 2688 | P5: =O5/$B$19 -> 4.249223e-05 | Q5: =P5*$A$22 -> 0.0008498446 | R5: =Q5*B26 -> 0.04249223 | S5: =R5/$B$22 -> 0.004249223 | U5: 0.00429295 | V5: =S5-U5 -> -4.3727001e-05
A6: H3 | B6: 3 | C6: 0 | D6: 0 | E6: 0 | F6: 6 | I6: 4xH2 | J6: =J5 -> 3 | K6: =K5 -> 1 | L6: =L5 -> 7 | M6: =M5 -> 32 | N6: =F18-N5 -> 44 | O6: =PRODUCT(J6:N6) -> 29568 | P6: =O6/$B$19 -> 0.00046741453 | Q6: =P6*$A$22 -> 0.0093482906 | R6: =Q6*C26 -> 0.11217949 | S6: =R6/$B$22 -> 0.011217949 | U6: 0.011234016 | V6: =S6-U6 -> -1.6067282e-05
A7: H4 | B7: 2 | C7: 8 | D7: 2 | E7: 0 | F7: 6 | I7: 3xH2 | J7: =J5 -> 3 | K7: =K5 -> 1 | L7: =L5 -> 7 | M7: =$E$18-$E$3-$E$5 -> 16 | N7: =F18 -> 48 | O7: =PRODUCT(J7:N7) -> 16128 | P7: =O7/$B$19 -> 0.00025495338 | Q7: =P7*$A$22 -> 0.0050990676 | R7: =Q7*D26 -> 0.010198135 | S7: =R7/$B$22 -> 0.0010198135 | U7: 0.001021698 | V7: =S7-U7 -> -1.8844802e-06
A8: L1 | B8: 4 | C8: 8 | D8: 4 | E8: 6 | F8: 5 | I8: 5xH3 | J8: =B3+B6 -> 3 | K8: =C3+C6 -> 1 | L8: =D3+D6 -> 3 | M8: =E3+E6 -> 28 | N8: =F3+F6 -> 6 | O8: =PRODUCT(J8:N8) -> 1512 | P8: =O8/$B$19 -> 2.3901879e-05 | Q8: =P8*$A$22 -> 0.00047803759 | R8: =Q8*B27 -> 0.023901879 | S8: =R8/$B$22 -> 0.0023901879 | U8: 0.00239075 | V8: =S8-U8 -> -5.6206294e-07
A9: L2 | B9: 7 | C9: 2 | D9: 2 | E9: 0 | F9: 6 | I9: 4xH3 | J9: =J8 -> 3 | K9: =K8 -> 1 | L9: =L8 -> 3 | M9: =M8 -> 28 | N9: =F18-N8 -> 42 | O9: =PRODUCT(J9:N9) -> 10584 | P9: =O9/$B$19 -> 0.00016731316 | Q9: =P9*$A$22 -> 0.0033462631 | R9: =Q9*C27 -> 0.040155157 | S9: =R9/$B$22 -> 0.0040155157 | U9: 0.004002768 | V9: =S9-U9 -> 1.2747734e-05
A10: L3 | B10: 7 | C10: 2 | D10: 2 | E10: 2 | F10: 6 | I10: 3xH3 | J10: =J9 -> 3 | K10: =K9 -> 1 | L10: =L9 -> 3 | M10: =E18-M9 -> 20 | N10: =F18 -> 48 | O10: =PRODUCT(J10:N10) -> 8640 | P10: =O10/$B$19 -> 0.00013658217 | Q10: =P10*$A$22 -> 0.0027316434 | R10: =Q10*D27 -> 0.0054632867 | S10: =R10/$B$22 -> 0.00054632867 | U10: 0.000545842 | V10: =S10-U10 -> 4.8667133e-07
A11: L4 | B11: 2 | C11: 6 | D11: 0 | E11: 0 | F11: 6 | I11: 5xH4 | J11: =B3+B7 -> 2 | K11: =C3+C7 -> 9 | L11: =D3+D7 -> 5 | M11: =E3+E7 -> 28 | N11: =F3+F7 -> 6 | O11: =PRODUCT(J11:N11) -> 15120 | P11: =O11/$B$19 -> 0.00023901879 | Q11: =P11*$A$22 -> 0.0047803759 | R11: =Q11*B28 -> 0.23901879 | S11: =R11/$B$22 -> 0.023901879 | U11: 0.02390365 | V11: =S11-U11 -> -1.7706294e-06
A12: L5 | B12: 2 | C12: 6 | D12: 0 | E12: 4 | F12: 6 | I12: 4xH4 | J12: =J11 -> 2 | K12: =K11 -> 9 | L12: =L11 -> 5 | M12: =M11 -> 28 | N12: =F18-N11 -> 42 | O12: =PRODUCT(J12:N12) -> 105840 | P12: =O12/$B$19 -> 0.0016731316 | Q12: =P12*$A$22 -> 0.033462631 | R12: =Q12*C28 -> 0.40155157 | S12: =R12/$B$22 -> 0.040155157 | U12: 0.040128372 | V12: =S12-U12 -> 2.6785343e-05
A13: SC | B13: 0 | C13: 0 | D13: 0 | E13: 0 | F13: 0 | I13: 3xH4 | J13: =J12 -> 2 | K13: =K12 -> 9 | L13: =L12 -> 5 | M13: =E18-M11 -> 20 | N13: =F18 -> 48 | O13: =PRODUCT(J13:N13) -> 86400 | P13: =O13/$B$19 -> 0.0013658217 | Q13: =P13*$A$22 -> 0.027316434 | R13: =Q13*D28 -> 0.054632867 | S13: =R13/$B$22 -> 0.0054632867 | U13: 0.005466732 | V13: =S13-U13 -> -3.4452867e-06
A14: RS | B14: 0 | C14: 0 | D14: 3 | E14: 0 | F14: 0 | I14: 5xL1 | J14: =B3+B8 -> 4 | K14: =C3+C8 -> 9 | L14: =D3+D8 -> 7 | M14: =E3+E8 -> 34 | N14: =F3+F8 -> 5 | O14: =PRODUCT(J14:N14) -> 42840 | P14: =O14/$B$19 -> 0.00067721992 | Q14: =P14*$A$22 -> 0.013544398 | R14: =Q14*B29 -> 0.54177593 | S14: =R14/$B$22 -> 0.054177593 | U14: 0.05410784 | V14: =S14-U14 -> 6.975324e-05
A15: Collect | B15: 0 | C15: 0 | D15: 0 | E15: 0 | F15: 0 | I15: 4xL1 | J15: =J14 -> 4 | K15: =K14 -> 9 | L15: =L14 -> 7 | M15: =M14 -> 34 | N15: =F18-N14 -> 43 | O15: =PRODUCT(J15:N15) -> 368424 | P15: =O15/$B$19 -> 0.0058240913 | Q15: =P15*$A$22 -> 0.11648183 | R15: =Q15*C29 -> 0.81537278 | S15: =R15/$B$22 -> 0.081537278 | U15: 0.081502519 | V15: =S15-U15 -> 3.4758826e-05
A16: Coin | B16: 0 | C16: 0 | D16: 0 | E16: 0 | F16: 0 | I16: 3xL1 | J16: =J14 -> 4 | K16: =K14 -> 9 | L16: =L14 -> 7 | M16: =E18-M14 -> 14 | N16: =F18 -> 48 | O16: =PRODUCT(J16:N16) -> 169344 | P16: =O16/$B$19 -> 0.0026770105 | Q16: =P16*$A$22 -> 0.05354021 | R16: =Q16*D29 -> 0.10708042 | S16: =R16/$B$22 -> 0.010708042 | U16: 0.010700866 | V16: =S16-U16 -> 7.175958e-06
A17: Res1 | B17: 0 | C17: 0 | D17: 0 | E17: 0 | F17: 0 | I17: 5xL2 | J17: =B3+B9 -> 7 | K17: =C3+C9 -> 3 | L17: =D3+D9 -> 5 | M17: =E3+E9 -> 28 | N17: =F3+F9 -> 6 | O17: =PRODUCT(J17:N17) -> 17640 | P17: =O17/$B$19 -> 0.00027885526 | Q17: =P17*$A$22 -> 0.0055771052 | R17: =Q17*B30 -> 0.13942763 | S17: =R17/$B$22 -> 0.013942763 | U17: 0.013933525 | V17: =S17-U17 -> 9.2379662e-06
A18: Total | B18: =SUM(B3:B17) -> 32 | C18: =SUM(C3:C17) -> 33 | D18: =SUM(D3:D17) -> 26 | E18: =SUM(E3:E17) -> 48 | F18: =SUM(F3:F17) -> 48 | I18: 4xL2 | J18: =J17 -> 7 | K18: =K17 -> 3 | L18: =L17 -> 5 | M18: =M17 -> 28 | N18: =F18-N17 -> 42 | O18: =PRODUCT(J18:N18) -> 123480 | P18: =O18/$B$19 -> 0.0019519868 | Q18: =P18*$A$22 -> 0.039039736 | R18: =Q18*C30 -> 0.19519868 | S18: =R18/$B$22 -> 0.019519868 | U18: 0.019495525 | V18: =S18-U18 -> 2.4343153e-05
A19: Total Cycles | B19: =PRODUCT(B18:F18) -> 63258624 | I19: 3xL2 | J19: =J17 -> 7 | K19: =K17 -> 3 | L19: =L17 -> 5 | M19: =E18-M17 -> 20 | N19: =F18 -> 48 | O19: =PRODUCT(J19:N19) -> 100800 | P19: =O19/$B$19 -> 0.0015934586 | Q19: =P19*$A$22 -> 0.031869172 | R19: =Q19*D30 -> 0.063738345 | S19: =R19/$B$22 -> 0.0063738345 | U19: 0.006372432 | V19: =S19-U19 -> 1.4024988e-06
I20: 5xL3 | J20: =B3+B10 -> 7 | K20: =C3+C10 -> 3 | L20: =D3+D10 -> 5 | M20: =E3+E10 -> 30 | N20: =F3+F10 -> 6 | O20: =PRODUCT(J20:N20) -> 18900 | P20: =O20/$B$19 -> 0.00029877349 | Q20: =P20*$A$22 -> 0.0059754698 | R20: =Q20*B31 -> 0.14938675 | S20: =R20/$B$22 -> 0.014938675 | U20: 0.014947475 | V20: =S20-U20 -> -8.8003934e-06
A21: Total Lines | B21: Wage | I21: 4xL3 | J21: =J20 -> 7 | K21: =K20 -> 3 | L21: =L20 -> 5 | M21: =M20 -> 30 | N21: =F18-N20 -> 42 | O21: =PRODUCT(J21:N21) -> 132300 | P21: =O21/$B$19 -> 0.0020914144 | Q21: =P21*$A$22 -> 0.041828289 | R21: =Q21*C31 -> 0.20914144 | S21: =R21/$B$22 -> 0.020914144 | U21: 0.020911275 | V21: =S21-U21 -> 2.8694493e-06
A22: 20 | B22: 10 | I22: 3xL3 | J22: =J20 -> 7 | K22: =K20 -> 3 | L22: =L20 -> 5 | M22: =E18-M20 -> 18 | N22: =F18 -> 48 | O22: =PRODUCT(J22:N22) -> 90720 | P22: =O22/$B$19 -> 0.0014341128 | Q22: =P22*$A$22 -> 0.028682255 | R22: =Q22*D31 -> 0.05736451 | S22: =R22/$B$22 -> 0.005736451 | U22: 0.005738548 | V22: =S22-U22 -> -2.096951e-06
I23: 5xL4 | J23: =B3+B11 -> 2 | K23: =C3+C11 -> 7 | L23: =D3+D11 -> 3 | M23: =E3+E11 -> 28 | N23: =F3+F11 -> 6 | O23: =PRODUCT(J23:N23) -> 7056 | P23: =O23/$B$19 -> 0.0001115421 | Q23: =P23*$A$22 -> 0.0022308421 | R23: =Q23*B32 -> 0.055771052 | S23: =R23/$B$22 -> 0.0055771052 | U23: 0.0055654 | V23: =S23-U23 -> 1.1705186e-05
A24: Symbol | B24: 5 OAK | C24: 4 OAK | D24: 3 OAK | I24: 4xL4 | J24: =J23 -> 2 | K24: =K23 -> 7 | L24: =L23 -> 3 | M24: =M23 -> 28 | N24: =F18-N23 -> 42 | O24: =PRODUCT(J24:N24) -> 49392 | P24: =O24/$B$19 -> 0.00078079473 | Q24: =P24*$A$22 -> 0.015615895 | R24: =Q24*C32 -> 0.078079473 | S24: =R24/$B$22 -> 0.0078079473 | U24: 0.00780677 | V24: =S24-U24 -> 1.1772611e-06
A25: H1 | B25: 75 | C25: 25 | D25: 2 | I25: 3xL4 | J25: =J23 -> 2 | K25: =K23 -> 7 | L25: =L23 -> 3 | M25: =E18-M23 -> 20 | N25: =F18 -> 48 | O25: =PRODUCT(J25:N25) -> 40320 | P25: =O25/$B$19 -> 0.00063738345 | Q25: =P25*$A$22 -> 0.012747669 | R25: =Q25*D32 -> 0.025495338 | S25: =R25/$B$22 -> 0.0025495338 | U25: 0.002547274 | V25: =S25-U25 -> 2.2597995e-06
A26: H2 | B26: 50 | C26: 12 | D26: 2 | I26: 5xL5 | J26: =B3+B12 -> 2 | K26: =C3+C12 -> 7 | L26: =D3+D12 -> 3 | M26: =E3+E12 -> 32 | N26: =F3+F12 -> 6 | O26: =PRODUCT(J26:N26) -> 8064 | P26: =O26/$B$19 -> 0.00012747669 | Q26: =P26*$A$22 -> 0.0025495338 | R26: =Q26*B33 -> 0.063738345 | S26: =R26/$B$22 -> 0.0063738345 | U26: 0.00637275 | V26: =S26-U26 -> 1.0844988e-06
A27: H3 | B27: 50 | C27: 12 | D27: 2 | I27: 4xL5 | J27: =J26 -> 2 | K27: =K26 -> 7 | L27: =L26 -> 3 | M27: =M26 -> 32 | N27: =F18-N26 -> 42 | O27: =PRODUCT(J27:N27) -> 56448 | P27: =O27/$B$19 -> 0.00089233683 | Q27: =P27*$A$22 -> 0.017846737 | R27: =Q27*C33 -> 0.089233683 | S27: =R27/$B$22 -> 0.0089233683 | U27: 0.00892398 | V27: =S27-U27 -> -6.1170163e-07
A28: H4 | B28: 50 | C28: 12 | D28: 2 | I28: 3xL5 | J28: =J26 -> 2 | K28: =K26 -> 7 | L28: =L26 -> 3 | M28: =E18-M26 -> 16 | N28: =F18 -> 48 | O28: =PRODUCT(J28:N28) -> 32256 | P28: =O28/$B$19 -> 0.00050990676 | Q28: =P28*$A$22 -> 0.010198135 | R28: =Q28*D33 -> 0.02039627 | S28: =R28/$B$22 -> 0.002039627 | U28: 0.002040074 | V28: =S28-U28 -> -4.4696037e-07
A29: L1 | B29: 40 | C29: 7 | D29: 2 | S29: =SUM(S2:S28) -> 0.37953832 | U29: =SUM(U2:U28) -> 0.37940935 | V29: =S29-U29 -> 0.00012896992
A30: L2 | B30: 25 | C30: 5 | D30: 2
A31: L3 | B31: 25 | C31: 5 | D31: 2
A32: L4 | B32: 25 | C32: 5 | D32: 2 | I32: H1,H1,RS,Any,Any | J32: =$B$3+$B$4 -> 2 | K32: =$C$3+$C$4 -> 1 | L32: =D14 -> 3 | M32: =$E$18 -> 48 | N32: =$F$18 -> 48 | O32: =PRODUCT(J32:N32) -> 13824 | P32: =O32/$B$19 -> 0.00021853147
A33: L5 | B33: 25 | C33: 5 | D33: 2 | I33: H2,H2,RS,Any,Any | J33: =$B$3+$B$5 -> 3 | K33: =$C$3+$C$5 -> 1 | L33: =$D$14 -> 3 | M33: =$E$18 -> 48 | N33: =$F$18 -> 48 | O33: =PRODUCT(J33:N33) -> 20736 | P33: =O33/$B$19 -> 0.0003277972
I34: H3,H3,RS,Any,Any | J34: =$B$3+$B$6 -> 3 | K34: =$C$3+C6 -> 1 | L34: =$D$14 -> 3 | M34: =$E$18 -> 48 | N34: =$F$18 -> 48 | O34: =PRODUCT(J34:N34) -> 20736 | P34: =O34/$B$19 -> 0.0003277972
I35: H4,H4,RS,Any,Any | J35: =$B$3+$B$7 -> 2 | K35: =$C$3+$C$7 -> 9 | L35: =$D$14 -> 3 | M35: =$E$18 -> 48 | N35: =$F$18 -> 48 | O35: =PRODUCT(J35:N35) -> 124416 | P35: =O35/$B$19 -> 0.0019667832
I36: L1,L1,RS,Any,Any | J36: =B3+B8 -> 4 | K36: =$C$3+$C$8 -> 9 | L36: =$D$14 -> 3 | M36: =$E$18 -> 48 | N36: =$F$18 -> 48 | O36: =PRODUCT(J36:N36) -> 248832 | P36: =O36/$B$19 -> 0.0039335664
A37: Choices | B37: Prob | C37: RTP | I37: L2,L2,RS,Any,Any | J37: =B3+B9 -> 7 | K37: =$C$3+$C$9 -> 3 | L37: =$D$14 -> 3 | M37: =$E$18 -> 48 | N37: =$F$18 -> 48 | O37: =PRODUCT(J37:N37) -> 145152 | P37: =O37/$B$19 -> 0.0022945804
A38: SC | B38: 1 | C38: =$S$29 -> 0.37953832 | D38: =B38*C38/$B$40 -> 0.18976916 | I38: L3,L3,RS,Any,Any | J38: =$B$3+$B$10 -> 7 | K38: =$C$3+$C$10 -> 3 | L38: =$D$14 -> 3 | M38: =$E$18 -> 48 | N38: =$F$18 -> 48 | O38: =PRODUCT(J38:N38) -> 145152 | P38: =O38/$B$19 -> 0.0022945804
A39: WD | B39: 1 | C39: ='Step-1'!S29 -> 1.1631039 | D39: =B39*C39/$B$40 -> 0.58155193 | I39: L4,L4,RS,Any,Any | J39: =$B$3+$B$11 -> 2 | K39: =$C$3+$C$11 -> 7 | L39: =$D$14 -> 3 | M39: =$E$18 -> 48 | N39: =$F$18 -> 48 | O39: =PRODUCT(J39:N39) -> 96768 | P39: =O39/$B$19 -> 0.0015297203
B40: =SUM(B38:B39) -> 2 | D40: =SUM(D38:D39) -> 0.77132109 | I40: L5,L5,RS,Any,Any | J40: =$B$3+$B$12 -> 2 | K40: =$C$3+$C$12 -> 7 | L40: =$D$14 -> 3 | M40: =$E$18 -> 48 | N40: =$F$18 -> 48 | O40: =PRODUCT(J40:N40) -> 96768 | P40: =O40/$B$19 -> 0.0015297203
...

Sheet Step-2B
A1: Symbol Set Population | B1: Symbol Set Population | C1: Symbol Set Population | D1: Symbol Set Population | E1: Symbol Set Population | F1: Symbol Set Population | I1: Prize | J1: R1 | K1: R2 | L1: R3 | M1: R4 | N1: R5 | O1: HITS | P1: Hit Rate | Q1: Total Hit Rate | R1: RTP(%) | S1: RTP(%) 1c
A2: Symbol | B2: BaseRS11R0 | C2: BaseRS11R1 | D2: BaseRS11R2 | E2: BaseRS11R3 | F2: BaseRS11R4 | I2: 5xH1 | J2: =B3+B4 -> 2 | K2: =C3+C4 -> 1 | L2: =D3+D4 -> 12 | M2: =E3+E4 -> 32 | N2: =F3+F4 -> 3 | O2: =PRODUCT(J2:N2) -> 2304 | P2: =O2/$B$19 -> 3.6421911e-05 | Q2: =P2*$A$22 -> 0.00072843823 | R2: =Q2*B25 -> 0.054632867 | S2: =R2/$B$22 -> 0.0054632867
A3: WD | B3: 0 | C3: 1 | D3: 6 | E3: 28 | F3: 0 | I3: 4xH1 | J3: =J2 -> 2 | K3: =K2 -> 1 | L3: =L2 -> 12 | M3: =M2 -> 32 | N3: =F18-N2 -> 45 | O3: =PRODUCT(J3:N3) -> 34560 | P3: =O3/$B$19 -> 0.00054632867 | Q3: =P3*$A$22 -> 0.010926573 | R3: =Q3*C25 -> 0.27316434 | S3: =R3/$B$22 -> 0.027316434
A4: H1 | B4: 2 | C4: 0 | D4: 6 | E4: 4 | F4: 3 | I4: 3xH1 | J4: =J2 -> 2 | K4: =K2 -> 1 | L4: =L2 -> 12 | M4: =E18-M2 -> 16 | N4: 48 | O4: =PRODUCT(J4:N4) -> 18432 | P4: =O4/$B$19 -> 0.00029137529 | Q4: =P4*$A$22 -> 0.0058275058 | R4: =Q4*D25 -> 0.011655012 | S4: =R4/$B$22 -> 0.0011655012
A5: H2 | B5: 3 | C5: 0 | D5: 4 | E5: 4 | F5: 4 | I5: 5xH2 | J5: =B3+B5 -> 3 | K5: =C3+C5 -> 1 | L5: =D3+D5 -> 10 | M5: =E3+E5 -> 32 | N5: =F3+F5 -> 4 | O5: =PRODUCT(J5:N5) -> 3840 | P5: =O5/$B$19 -> 6.0703186e-05 | Q5: =P5*$A$22 -> 0.0012140637 | R5: =Q5*B26 -> 0.060703186 | S5: =R5/$B$22 -> 0.0060703186
A6: H3 | B6: 3 | C6: 0 | D6: 0 | E6: 0 | F6: 6 | I6: 4xH2 | J6: =J5 -> 3 | K6: =K5 -> 1 | L6: =L5 -> 10 | M6: =M5 -> 32 | N6: =F18-N5 -> 44 | O6: =PRODUCT(J6:N6) -> 42240 | P6: =O6/$B$19 -> 0.00066773504 | Q6: =P6*$A$22 -> 0.013354701 | R6: =Q6*C26 -> 0.16025641 | S6: =R6/$B$22 -> 0.016025641
A7: H4 | B7: 2 | C7: 8 | D7: 2 | E7: 0 | F7: 6 | I7: 3xH2 | J7: =J5 -> 3 | K7: =K5 -> 1 | L7: =L5 -> 10 | M7: =$E$18-$E$3-$E$5 -> 16 | N7: =F18 -> 48 | O7: =PRODUCT(J7:N7) -> 23040 | P7: =O7/$B$19 -> 0.00036421911 | Q7: =P7*$A$22 -> 0.0072843823 | R7: =Q7*D26 -> 0.014568765 | S7: =R7/$B$22 -> 0.0014568765
A8: L1 | B8: 4 | C8: 8 | D8: 4 | E8: 6 | F8: 5 | I8: 5xH3 | J8: =B3+B6 -> 3 | K8: =C3+C6 -> 1 | L8: =D3+D6 -> 6 | M8: =E3+E6 -> 28 | N8: =F3+F6 -> 6 | O8: =PRODUCT(J8:N8) -> 3024 | P8: =O8/$B$19 -> 4.7803759e-05 | Q8: =P8*$A$22 -> 0.00095607517 | R8: =Q8*B27 -> 0.047803759 | S8: =R8/$B$22 -> 0.0047803759
A9: L2 | B9: 7 | C9: 2 | D9: 2 | E9: 0 | F9: 6 | I9: 4xH3 | J9: =J8 -> 3 | K9: =K8 -> 1 | L9: =L8 -> 6 | M9: =M8 -> 28 | N9: =F18-N8 -> 42 | O9: =PRODUCT(J9:N9) -> 21168 | P9: =O9/$B$19 -> 0.00033462631 | Q9: =P9*$A$22 -> 0.0066925262 | R9: =Q9*C27 -> 0.080310315 | S9: =R9/$B$22 -> 0.0080310315
A10: L3 | B10: 7 | C10: 2 | D10: 2 | E10: 2 | F10: 6 | I10: 3xH3 | J10: =J9 -> 3 | K10: =K9 -> 1 | L10: =L9 -> 6 | M10: =E18-M9 -> 20 | N10: =F18 -> 48 | O10: =PRODUCT(J10:N10) -> 17280 | P10: =O10/$B$19 -> 0.00027316434 | Q10: =P10*$A$22 -> 0.0054632867 | R10: =Q10*D27 -> 0.010926573 | S10: =R10/$B$22 -> 0.0010926573
A11: L4 | B11: 2 | C11: 6 | D11: 0 | E11: 0 | F11: 6 | I11: 5xH4 | J11: =B3+B7 -> 2 | K11: =C3+C7 -> 9 | L11: =D3+D7 -> 8 | M11: =E3+E7 -> 28 | N11: =F3+F7 -> 6 | O11: =PRODUCT(J11:N11) -> 24192 | P11: =O11/$B$19 -> 0.00038243007 | Q11: =P11*$A$22 -> 0.0076486014 | R11: =Q11*B28 -> 0.38243007 | S11: =R11/$B$22 -> 0.038243007
A12: L5 | B12: 2 | C12: 6 | D12: 0 | E12: 4 | F12: 6 | I12: 4xH4 | J12: =J11 -> 2 | K12: =K11 -> 9 | L12: =L11 -> 8 | M12: =M11 -> 28 | N12: =F18-N11 -> 42 | O12: =PRODUCT(J12:N12) -> 169344 | P12: =O12/$B$19 -> 0.0026770105 | Q12: =P12*$A$22 -> 0.05354021 | R12: =Q12*C28 -> 0.64248252 | S12: =R12/$B$22 -> 0.064248252
A13: SC | B13: 0 | C13: 0 | D13: 0 | E13: 0 | F13: 0 | I13: 3xH4 | J13: =J12 -> 2 | K13: =K12 -> 9 | L13: =L12 -> 8 | M13: =E18-M11 -> 20 | N13: =F18 -> 48 | O13: =PRODUCT(J13:N13) -> 138240 | P13: =O13/$B$19 -> 0.0021853147 | Q13: =P13*$A$22 -> 0.043706294 | R13: =Q13*D28 -> 0.087412587 | S13: =R13/$B$22 -> 0.0087412587
A14: RS | B14: 0 | C14: 0 | D14: 0 | E14: 0 | F14: 0 | I14: 5xL1 | J14: =B3+B8 -> 4 | K14: =C3+C8 -> 9 | L14: =D3+D8 -> 10 | M14: =E3+E8 -> 34 | N14: =F3+F8 -> 5 | O14: =PRODUCT(J14:N14) -> 61200 | P14: =O14/$B$19 -> 0.00096745702 | Q14: =P14*$A$22 -> 0.01934914 | R14: =Q14*B29 -> 0.77396562 | S14: =R14/$B$22 -> 0.077396562
A15: Collect | B15: 0 | C15: 0 | D15: 0 | E15: 0 | F15: 0 | I15: 4xL1 | J15: =J14 -> 4 | K15: =K14 -> 9 | L15: =L14 -> 10 | M15: =M14 -> 34 | N15: =F18-N14 -> 43 | O15: =PRODUCT(J15:N15) -> 526320 | P15: =O15/$B$19 -> 0.0083201304 | Q15: =P15*$A$22 -> 0.16640261 | R15: =Q15*C29 -> 1.1648183 | S15: =R15/$B$22 -> 0.11648183
A16: Coin | B16: 0 | C16: 0 | D16: 0 | E16: 0 | F16: 0 | I16: 3xL1 | J16: =J14 -> 4 | K16: =K14 -> 9 | L16: =L14 -> 10 | M16: =E18-M14 -> 14 | N16: =F18 -> 48 | O16: =PRODUCT(J16:N16) -> 241920 | P16: =O16/$B$19 -> 0.0038243007 | Q16: =P16*$A$22 -> 0.076486014 | R16: =Q16*D29 -> 0.15297203 | S16: =R16/$B$22 -> 0.015297203
A17: Res1 | B17: 0 | C17: 0 | D17: 0 | E17: 0 | F17: 0 | I17: 5xL2 | J17: =B3+B9 -> 7 | K17: =C3+C9 -> 3 | L17: =D3+D9 -> 8 | M17: =E3+E9 -> 28 | N17: =F3+F9 -> 6 | O17: =PRODUCT(J17:N17) -> 28224 | P17: =O17/$B$19 -> 0.00044616841 | Q17: =P17*$A$22 -> 0.0089233683 | R17: =Q17*B30 -> 0.22308421 | S17: =R17/$B$22 -> 0.022308421
A18: Total | B18: =SUM(B3:B17) -> 32 | C18: =SUM(C3:C17) -> 33 | D18: =SUM(D3:D17) -> 26 | E18: =SUM(E3:E17) -> 48 | F18: =SUM(F3:F17) -> 48 | I18: 4xL2 | J18: =J17 -> 7 | K18: =K17 -> 3 | L18: =L17 -> 8 | M18: =M17 -> 28 | N18: =F18-N17 -> 42 | O18: =PRODUCT(J18:N18) -> 197568 | P18: =O18/$B$19 -> 0.0031231789 | Q18: =P18*$A$22 -> 0.062463578 | R18: =Q18*C30 -> 0.31231789 | S18: =R18/$B$22 -> 0.031231789
A19: Total Cycles | B19: =PRODUCT(B18:F18) -> 63258624 | I19: 3xL2 | J19: =J17 -> 7 | K19: =K17 -> 3 | L19: =L17 -> 8 | M19: =E18-M17 -> 20 | N19: =F18 -> 48 | O19: =PRODUCT(J19:N19) -> 161280 | P19: =O19/$B$19 -> 0.0025495338 | Q19: =P19*$A$22 -> 0.050990676 | R19: =Q19*D30 -> 0.10198135 | S19: =R19/$B$22 -> 0.010198135
I20: 5xL3 | J20: =B3+B10 -> 7 | K20: =C3+C10 -> 3 | L20: =D3+D10 -> 8 | M20: =E3+E10 -> 30 | N20: =F3+F10 -> 6 | O20: =PRODUCT(J20:N20) -> 30240 | P20: =O20/$B$19 -> 0.00047803759 | Q20: =P20*$A$22 -> 0.0095607517 | R20: =Q20*B31 -> 0.23901879 | S20: =R20/$B$22 -> 0.023901879
A21: Total Lines | B21: Wage | I21: 4xL3 | J21: =J20 -> 7 | K21: =K20 -> 3 | L21: =L20 -> 8 | M21: =M20 -> 30 | N21: =F18-N20 -> 42 | O21: =PRODUCT(J21:N21) -> 211680 | P21: =O21/$B$19 -> 0.0033462631 | Q21: =P21*$A$22 -> 0.066925262 | R21: =Q21*C31 -> 0.33462631 | S21: =R21/$B$22 -> 0.033462631
A22: 20 | B22: 10 | I22: 3xL3 | J22: =J20 -> 7 | K22: =K20 -> 3 | L22: =L20 -> 8 | M22: =E18-M20 -> 18 | N22: =F18 -> 48 | O22: =PRODUCT(J22:N22) -> 145152 | P22: =O22/$B$19 -> 0.0022945804 | Q22: =P22*$A$22 -> 0.045891608 | R22: =Q22*D31 -> 0.091783217 | S22: =R22/$B$22 -> 0.0091783217
I23: 5xL4 | J23: =B3+B11 -> 2 | K23: =C3+C11 -> 7 | L23: =D3+D11 -> 6 | M23: =E3+E11 -> 28 | N23: =F3+F11 -> 6 | O23: =PRODUCT(J23:N23) -> 14112 | P23: =O23/$B$19 -> 0.00022308421 | Q23: =P23*$A$22 -> 0.0044616841 | R23: =Q23*B32 -> 0.1115421 | S23: =R23/$B$22 -> 0.01115421
A24: Symbol | B24: 5 OAK | C24: 4 OAK | D24: 3 OAK | I24: 4xL4 | J24: =J23 -> 2 | K24: =K23 -> 7 | L24: =L23 -> 6 | M24: =M23 -> 28 | N24: =F18-N23 -> 42 | O24: =PRODUCT(J24:N24) -> 98784 | P24: =O24/$B$19 -> 0.0015615895 | Q24: =P24*$A$22 -> 0.031231789 | R24: =Q24*C32 -> 0.15615895 | S24: =R24/$B$22 -> 0.015615895
A25: H1 | B25: 75 | C25: 25 | D25: 2 | I25: 3xL4 | J25: =J23 -> 2 | K25: =K23 -> 7 | L25: =L23 -> 6 | M25: =E18-M23 -> 20 | N25: =F18 -> 48 | O25: =PRODUCT(J25:N25) -> 80640 | P25: =O25/$B$19 -> 0.0012747669 | Q25: =P25*$A$22 -> 0.025495338 | R25: =Q25*D32 -> 0.050990676 | S25: =R25/$B$22 -> 0.0050990676
A26: H2 | B26: 50 | C26: 12 | D26: 2 | I26: 5xL5 | J26: =B3+B12 -> 2 | K26: =C3+C12 -> 7 | L26: =D3+D12 -> 6 | M26: =E3+E12 -> 32 | N26: =F3+F12 -> 6 | O26: =PRODUCT(J26:N26) -> 16128 | P26: =O26/$B$19 -> 0.00025495338 | Q26: =P26*$A$22 -> 0.0050990676 | R26: =Q26*B33 -> 0.12747669 | S26: =R26/$B$22 -> 0.012747669
A27: H3 | B27: 50 | C27: 12 | D27: 2 | I27: 4xL5 | J27: =J26 -> 2 | K27: =K26 -> 7 | L27: =L26 -> 6 | M27: =M26 -> 32 | N27: =F18-N26 -> 42 | O27: =PRODUCT(J27:N27) -> 112896 | P27: =O27/$B$19 -> 0.0017846737 | Q27: =P27*$A$22 -> 0.035693473 | R27: =Q27*C33 -> 0.17846737 | S27: =R27/$B$22 -> 0.017846737
A28: H4 | B28: 50 | C28: 12 | D28: 2 | I28: 3xL5 | J28: =J26 -> 2 | K28: =K26 -> 7 | L28: =L26 -> 6 | M28: =E18-M26 -> 16 | N28: =F18 -> 48 | O28: =PRODUCT(J28:N28) -> 64512 | P28: =O28/$B$19 -> 0.0010198135 | Q28: =P28*$A$22 -> 0.02039627 | R28: =Q28*D33 -> 0.040792541 | S28: =R28/$B$22 -> 0.0040792541
A29: L1 | B29: 40 | C29: 7 | D29: 2 | Q29: =SUM(Q2:Q28) -> 0.78671329 | S29: =SUM(S2:S28) -> 0.58863424
A30: L2 | B30: 25 | C30: 5 | D30: 2
A31: L3 | B31: 25 | C31: 5 | D31: 2
A32: L4 | B32: 25 | C32: 5 | D32: 2
A33: L5 | B33: 25 | C33: 5 | D33: 2
A37: Choices | B37: Weight | C37: Prob | D37: Rtp
A38: SC | B38: 30 | C38: =B38/$B$40 -> 0.3 | D38: ='Step-2'!S29 -> 0.37953832
A39: WD | B39: 70 | C39: =B39/$B$40 -> 0.7 | D39: =S29 -> 0.58863424
B40: =SUM(B38:B39) -> 100 | D40: =SUMPRODUCT(C38:C39,D38:D39) -> 0.52590546

Sheet Step-3
A1: Symbol Set Population | B1: Symbol Set Population | C1: Symbol Set Population | D1: Symbol Set Population | E1: Symbol Set Population | F1: Symbol Set Population | H1: Prize | I1: R1 | J1: R2 | K1: R3 | L1: R4 | M1: R5 | N1: HITS | O1: Hit Rate
A2: Symbol | B2: BaseRS11R0 | C2: BaseRS11R1 | D2: BaseRS11R2 | E2: BaseRS11R3 | F2: BaseRS11R4 | H2: 5xH1 | I2: =B3+B4 -> 2 | J2: =$C$3+$C$4 -> 1 | K2: =$D$14 -> 3 | L2: =E3+E4 -> 32 | M2: =F3+F4 -> 3 | N2: =PRODUCT(I2:M2) -> 576 | O2: =N2/$B$19 -> 9.1054779e-06
A3: WD | B3: 0 | C3: 1 | D3: 3 | E3: 28 | F3: 0 | H3: 4xH1 | I3: =I2 -> 2 | J3: =J2 -> 1 | K3: =$D$14 -> 3 | L3: =L2 -> 32 | M3: =F18-M2 -> 45 | N3: =PRODUCT(I3:M3) -> 8640 | O3: =N3/$B$19 -> 0.00013658217
A4: H1 | B4: 2 | C4: 0 | D4: 6 | E4: 4 | F4: 3 | H4: 3xH1 | I4: =I2 -> 2 | J4: =J2 -> 1 | K4: =$D$14 -> 3 | L4: =E18-L2 -> 16 | M4: 48 | N4: =PRODUCT(I4:M4) -> 4608 | O4: =N4/$B$19 -> 7.2843823e-05
A5: H2 | B5: 3 | C5: 0 | D5: 4 | E5: 4 | F5: 4 | H5: 5xH2 | I5: =B3+B5 -> 3 | J5: =C3+C5 -> 1 | K5: =$D$14 -> 3 | L5: =E3+E5 -> 32 | M5: =F3+F5 -> 4 | N5: =PRODUCT(I5:M5) -> 1152 | O5: =N5/$B$19 -> 1.8210956e-05
A6: H3 | B6: 3 | C6: 0 | D6: 0 | E6: 0 | F6: 6 | H6: 4xH2 | I6: =I5 -> 3 | J6: =J5 -> 1 | K6: =$D$14 -> 3 | L6: =L5 -> 32 | M6: =F18-M5 -> 44 | N6: =PRODUCT(I6:M6) -> 12672 | O6: =N6/$B$19 -> 0.00020032051
A7: H4 | B7: 2 | C7: 8 | D7: 2 | E7: 0 | F7: 6 | H7: 3xH2 | I7: =I5 -> 3 | J7: =J5 -> 1 | K7: =$D$14 -> 3 | L7: =$E$18-$E$3-$E$5 -> 16 | M7: =F18 -> 48 | N7: =PRODUCT(I7:M7) -> 6912 | O7: =N7/$B$19 -> 0.00010926573
A8: L1 | B8: 4 | C8: 8 | D8: 4 | E8: 6 | F8: 5 | H8: 5xH3 | I8: =$B$3+$B$6 -> 3 | J8: =$C$3+$C$6 -> 1 | K8: =$D$14 -> 3 | L8: =E3+E6 -> 28 | M8: =F3+F6 -> 6 | N8: =PRODUCT(I8:M8) -> 1512 | O8: =N8/$B$19 -> 2.3901879e-05
A9: L2 | B9: 7 | C9: 2 | D9: 2 | E9: 0 | F9: 6 | H9: 4xH3 | I9: =$B$3+$B$6 -> 3 | J9: =$C$3+$C$6 -> 1 | K9: =$D$14 -> 3 | L9: =L8 -> 28 | M9: =F18-M8 -> 42 | N9: =PRODUCT(I9:M9) -> 10584 | O9: =N9/$B$19 -> 0.00016731316
A10: L3 | B10: 7 | C10: 2 | D10: 2 | E10: 2 | F10: 6 | H10: 3xH3 | I10: =$B$3+$B$6 -> 3 | J10: =$C$3+$C$6 -> 1 | K10: =$D$14 -> 3 | L10: =E18-L9 -> 20 | M10: =F18 -> 48 | N10: =PRODUCT(I10:M10) -> 8640 | O10: =N10/$B$19 -> 0.00013658217
A11: L4 | B11: 2 | C11: 6 | D11: 0 | E11: 0 | F11: 6 | H11: 5xH4 | I11: =$B$3+$B$7 -> 2 | J11: =$C$3+$C$7 -> 9 | K11: =$D$14 -> 3 | L11: =E3+E7 -> 28 | M11: =F3+F7 -> 6 | N11: =PRODUCT(I11:M11) -> 9072 | O11: =N11/$B$19 -> 0.00014341128
A12: L5 | B12: 2 | C12: 6 | D12: 0 | E12: 4 | F12: 6 | H12: 4xH4 | I12: =I11 -> 2 | J12: =J11 -> 9 | K12: =$D$14 -> 3 | L12: =L11 -> 28 | M12: =F18-M11 -> 42 | N12: =PRODUCT(I12:M12) -> 63504 | O12: =N12/$B$19 -> 0.0010038789
A13: SC | B13: 0 | C13: 0 | D13: 0 | E13: 0 | F13: 0 | H13: 3xH4 | I13: =I12 -> 2 | J13: =J12 -> 9 | K13: =$D$14 -> 3 | L13: =E18-L11 -> 20 | M13: =F18 -> 48 | N13: =PRODUCT(I13:M13) -> 51840 | O13: =N13/$B$19 -> 0.00081949301
A14: RS | B14: 0 | C14: 0 | D14: 3 | E14: 0 | F14: 0 | H14: 5xL1 | I14: =$B$3+$B$8 -> 4 | J14: =$C$3+$C$8 -> 9 | K14: =$D$14 -> 3 | L14: =E3+E8 -> 34 | M14: =F3+F8 -> 5 | N14: =PRODUCT(I14:M14) -> 18360 | O14: =N14/$B$19 -> 0.00029023711
A15: Collect | B15: 0 | C15: 0 | D15: 0 | E15: 0 | F15: 0 | H15: 4xL1 | I15: =$B$3+$B$8 -> 4 | J15: =$C$3+$C$8 -> 9 | K15: =$D$14 -> 3 | L15: =L14 -> 34 | M15: =F18-M14 -> 43 | N15: =PRODUCT(I15:M15) -> 157896 | O15: =N15/$B$19 -> 0.0024960391
A16: Coin | B16: 0 | C16: 0 | D16: 0 | E16: 0 | F16: 0 | H16: 3xL1 | I16: =$B$3+$B$8 -> 4 | J16: =$C$3+$C$8 -> 9 | K16: =$D$14 -> 3 | L16: =E18-L14 -> 14 | M16: =F18 -> 48 | N16: =PRODUCT(I16:M16) -> 72576 | O16: =N16/$B$19 -> 0.0011472902
A17: Res1 | B17: 0 | C17: 0 | D17: 0 | E17: 0 | F17: 0 | H17: 5xL2 | I17: =B3+B9 -> 7 | J17: =C3+C9 -> 3 | K17: =$D$14 -> 3 | L17: =E3+E9 -> 28 | M17: =F3+F9 -> 6 | N17: =PRODUCT(I17:M17) -> 10584 | O17: =N17/$B$19 -> 0.00016731316
A18: Total | B18: =SUM(B3:B17) -> 32 | C18: =SUM(C3:C17) -> 33 | D18: =SUM(D3:D17) -> 26 | E18: =SUM(E3:E17) -> 48 | F18: =SUM(F3:F17) -> 48 | H18: 4xL2 | I18: =I17 -> 7 | J18: =J17 -> 3 | K18: =$D$14 -> 3 | L18: =L17 -> 28 | M18: =F18-M17 -> 42 | N18: =PRODUCT(I18:M18) -> 74088 | O18: =N18/$B$19 -> 0.0011711921
A19: Total Cycles | B19: =PRODUCT(B18:F18) -> 63258624 | H19: 3xL2 | I19: =I17 -> 7 | J19: =J17 -> 3 | K19: =$D$14 -> 3 | L19: =E18-L17 -> 20 | M19: =F18 -> 48 | N19: =PRODUCT(I19:M19) -> 60480 | O19: =N19/$B$19 -> 0.00095607517
H20: 5xL3 | I20: =B3+B10 -> 7 | J20: =C3+C10 -> 3 | K20: =$D$14 -> 3 | L20: =E3+E10 -> 30 | M20: =F3+F10 -> 6 | N20: =PRODUCT(I20:M20) -> 11340 | O20: =N20/$B$19 -> 0.0001792641
A21: Total Lines | B21: Wage | H21: 4xL3 | I21: =I20 -> 7 | J21: =J20 -> 3 | K21: =$D$14 -> 3 | L21: =L20 -> 30 | M21: =F18-M20 -> 42 | N21: =PRODUCT(I21:M21) -> 79380 | O21: =N21/$B$19 -> 0.0012548487
A22: 20 | B22: 10 | H22: 3xL3 | I22: =I20 -> 7 | J22: =J20 -> 3 | K22: =$D$14 -> 3 | L22: =E18-L20 -> 18 | M22: =F18 -> 48 | N22: =PRODUCT(I22:M22) -> 54432 | O22: =N22/$B$19 -> 0.00086046766
H23: 5xL4 | I23: =B3+B11 -> 2 | J23: =C3+C11 -> 7 | K23: =$D$14 -> 3 | L23: =E3+E11 -> 28 | M23: =F3+F11 -> 6 | N23: =PRODUCT(I23:M23) -> 7056 | O23: =N23/$B$19 -> 0.0001115421
A24: Symbol | B24: 5 OAK | C24: 4 OAK | D24: 3 OAK | H24: 4xL4 | I24: =I23 -> 2 | J24: =J23 -> 7 | K24: =$D$14 -> 3 | L24: =L23 -> 28 | M24: =F18-M23 -> 42 | N24: =PRODUCT(I24:M24) -> 49392 | O24: =N24/$B$19 -> 0.00078079473
A25: H1 | B25: 75 | C25: 25 | D25: 2 | H25: 3xL4 | I25: =I23 -> 2 | J25: =J23 -> 7 | K25: =$D$14 -> 3 | L25: =E18-L23 -> 20 | M25: =F18 -> 48 | N25: =PRODUCT(I25:M25) -> 40320 | O25: =N25/$B$19 -> 0.00063738345
A26: H2 | B26: 50 | C26: 12 | D26: 2 | H26: 5xL5 | I26: =B3+B12 -> 2 | J26: =C3+C12 -> 7 | K26: =$D$14 -> 3 | L26: =E3+E12 -> 32 | M26: =F3+F12 -> 6 | N26: =PRODUCT(I26:M26) -> 8064 | O26: =N26/$B$19 -> 0.00012747669
A27: H3 | B27: 50 | C27: 12 | D27: 2 | H27: 4xL5 | I27: =I26 -> 2 | J27: =J26 -> 7 | K27: =$D$14 -> 3 | L27: =L26 -> 32 | M27: =F18-M26 -> 42 | N27: =PRODUCT(I27:M27) -> 56448 | O27: =N27/$B$19 -> 0.00089233683
A28: H4 | B28: 50 | C28: 12 | D28: 2 | H28: 3xL5 | I28: =I26 -> 2 | J28: =J26 -> 7 | K28: =$D$14 -> 3 | L28: =E18-L26 -> 16 | M28: =F18 -> 48 | N28: =PRODUCT(I28:M28) -> 32256 | O28: =N28/$B$19 -> 0.00050990676
A29: L1 | B29: 40 | C29: 7 | D29: 2 | O29: =SUM(O2:O28) -> 0.014423077
A30: L2 | B30: 25 | C30: 5 | D30: 2
A31: L3 | B31: 25 | C31: 5 | D31: 2
A32: L4 | B32: 25 | C32: 5 | D32: 2
A33: L5 | B33: 25 | C33: 5 | D33: 2

Sheet Step-4
A1: Symbol Set Population | B1: Symbol Set Population | C1: Symbol Set Population | D1: Symbol Set Population | E1: Symbol Set Population | F1: Symbol Set Population | I1: Prize | J1: R1 | K1: R2 | L1: R3 | M1: R4 | N1: R5 | O1: HITS | P1: Hit Rate | Q1: Total Hit Rate | R1: RTP(%) | S1: RTP(%) 1c | W1: Prize With RS | X1: R1 | Y1: R2 | Z1: R3 | AA1: R4 | AB1: R5 | AC1: HITS | AD1: Hit Rate | AE1: Total Hit Rate | AF1: RTP(%) | AG1: RTP(%) 1c
A2: Symbol | B2: BaseRS11R0 | C2: BaseRS11R1 | D2: BaseRS11R2 | E2: BaseRS11R3 | F2: BaseRS11R4 | I2: 5xH1 | J2: =B3+B4 -> 2 | K2: =C3+C4 -> 1 | L2: =D3+D4 -> 9 | M2: =E3+E4 -> 32 | N2: =F3+F4 -> 3 | O2: =PRODUCT(J2:N2) -> 1728 | P2: =O2/$B$19 -> 2.0882833e-05 | Q2: =P2*$A$22 -> 0.00041765667 | R2: =Q2*B25 -> 0.03132425 | S2: =R2/$B$22 -> 0.003132425 | W2: 5xH1 | X2: =$B$3+$B$4 -> 2 | Y2: =$C$3+$C$4 -> 1 | Z2: =$D$14 -> 3 | AA2: =$E$3+$E$4 -> 32 | AB2: =$F$3+$F$4 -> 3 | AC2: =PRODUCT(X2:AB2) -> 576 | AD2: =AC2/$B$19 -> 6.9609445e-06 | AE2: =AD2*$A$22 -> 0.00013921889 | AF2: =AE2*B25 -> 0.010441417 | AG2: =AF2/$B$22 -> 0.0010441417
A3: WD | B3: 0 | C3: 1 | D3: 3 | E3: 28 | F3: 0 | I3: 4xH1 | J3: =J2 -> 2 | K3: =K2 -> 1 | L3: =L2 -> 9 | M3: =M2 -> 32 | N3: =F18-N2 -> 45 | O3: =PRODUCT(J3:N3) -> 25920 | P3: =O3/$B$19 -> 0.0003132425 | Q3: =P3*$A$22 -> 0.00626485 | R3: =Q3*C25 -> 0.15662125 | S3: =R3/$B$22 -> 0.015662125 | W3: 4xH1 | X3: =$B$3+$B$4 -> 2 | Y3: =$C$3+$C$4 -> 1 | Z3: =$D$14 -> 3 | AA3: =$E$3+$E$4 -> 32 | AB3: =$F$18-$F$3-$F$4 -> 45 | AC3: =PRODUCT(X3:AB3) -> 8640 | AD3: =AC3/$B$19 -> 0.00010441417 | AE3: =AD3*$A$22 -> 0.0020882833 | AF3: =AE3*C25 -> 0.052207083 | AG3: =AF3/$B$22 -> 0.0052207083
A4: H1 | B4: 2 | C4: 0 | D4: 6 | E4: 4 | F4: 3 | I4: 3xH1 | J4: =J2 -> 2 | K4: =K2 -> 1 | L4: =L2 -> 9 | M4: =E18-M2 -> 20 | N4: 48 | O4: =PRODUCT(J4:N4) -> 17280 | P4: =O4/$B$19 -> 0.00020882833 | Q4: =P4*$A$22 -> 0.0041765667 | R4: =Q4*D25 -> 0.0083531334 | S4: =R4/$B$22 -> 0.00083531334 | W4: 3xH1 | X4: =$B$3+$B$4 -> 2 | Y4: =$C$3+$C$4 -> 1 | Z4: =$D$14 -> 3 | AA4: =$E$18-$E$3-$E$4 -> 20 | AB4: =$F$18 -> 48 | AC4: =PRODUCT(X4:AB4) -> 5760 | AD4: =AC4/$B$19 -> 6.9609445e-05 | AE4: =AD4*$A$22 -> 0.0013921889 | AF4: =AE4*D25 -> 0.0027843778 | AG4: =AF4/$B$22 -> 0.00027843778
A5: H2 | B5: 3 | C5: 0 | D5: 4 | E5: 4 | F5: 4 | I5: 5xH2 | J5: =B3+B5 -> 3 | K5: =C3+C5 -> 1 | L5: =D3+D5 -> 7 | M5: =E3+E5 -> 32 | N5: =F3+F5 -> 4 | O5: =PRODUCT(J5:N5) -> 2688 | P5: =O5/$B$19 -> 3.2484407e-05 | Q5: =P5*$A$22 -> 0.00064968815 | R5: =Q5*B26 -> 0.032484407 | S5: =R5/$B$22 -> 0.0032484407 | W5: 5xH2 | X5: =$B$3+$B$5 -> 3 | Y5: =$C$3+$C$5 -> 1 | Z5: =$D$14 -> 3 | AA5: =$E$3+$E$5 -> 32 | AB5: =$F$3+$F$5 -> 4 | AC5: =PRODUCT(X5:AB5) -> 1152 | AD5: =AC5/$B$19 -> 1.3921889e-05 | AE5: =AD5*$A$22 -> 0.00027843778 | AF5: =AE5*$B$26 -> 0.013921889 | AG5: =AF5/$B$22 -> 0.0013921889
A6: H3 | B6: 3 | C6: 0 | D6: 0 | E6: 0 | F6: 6 | I6: 4xH2 | J6: =J5 -> 3 | K6: =K5 -> 1 | L6: =L5 -> 7 | M6: =M5 -> 32 | N6: =F18-N5 -> 44 | O6: =PRODUCT(J6:N6) -> 29568 | P6: =O6/$B$19 -> 0.00035732848 | Q6: =P6*$A$22 -> 0.0071465696 | R6: =Q6*C26 -> 0.085758836 | S6: =R6/$B$22 -> 0.0085758836 | W6: 4xH2 | X6: =$B$3+$B$5 -> 3 | Y6: =$C$3+$C$5 -> 1 | Z6: =$D$14 -> 3 | AA6: =$E$3+$E$5 -> 32 | AB6: =$F$18-$F$3-$F$5 -> 44 | AC6: =PRODUCT(X6:AB6) -> 12672 | AD6: =AC6/$B$19 -> 0.00015314078 | AE6: =AD6*$A$22 -> 0.0030628156 | AF6: =AE6*$C$26 -> 0.036753787 | AG6: =AF6/$B$22 -> 0.0036753787
A7: H4 | B7: 2 | C7: 8 | D7: 2 | E7: 0 | F7: 6 | I7: 3xH2 | J7: =J5 -> 3 | K7: =K5 -> 1 | L7: =L5 -> 7 | M7: =$E$18-$E$3-$E$5 -> 20 | N7: =F18 -> 48 | O7: =PRODUCT(J7:N7) -> 20160 | P7: =O7/$B$19 -> 0.00024363306 | Q7: =P7*$A$22 -> 0.0048726611 | R7: =Q7*D26 -> 0.0097453222 | S7: =R7/$B$22 -> 0.00097453222 | W7: 3xH2 | X7: =$B$3+$B$5 -> 3 | Y7: =$C$3+$C$5 -> 1 | Z7: =$D$14 -> 3 | AA7: =$E$18-$E$3-$E$5 -> 20 | AB7: =$F$18 -> 48 | AC7: =PRODUCT(X7:AB7) -> 8640 | AD7: =AC7/$B$19 -> 0.00010441417 | AE7: =AD7*$A$22 -> 0.0020882833 | AF7: =AE7*$D$26 -> 0.0041765667 | AG7: =AF7/$B$22 -> 0.00041765667
A8: L1 | B8: 4 | C8: 8 | D8: 4 | E8: 6 | F8: 5 | I8: 5xH3 | J8: =B3+B6 -> 3 | K8: =C3+C6 -> 1 | L8: =D3+D6 -> 3 | M8: =E3+E6 -> 28 | N8: =F3+F6 -> 6 | O8: =PRODUCT(J8:N8) -> 1512 | P8: =O8/$B$19 -> 1.8272479e-05 | Q8: =P8*$A$22 -> 0.00036544958 | R8: =Q8*B27 -> 0.018272479 | S8: =R8/$B$22 -> 0.0018272479 | W8: 5xH3 | X8: =$B$3+$B$6 -> 3 | Y8: =$C$3+$C$6 -> 1 | Z8: =$D$14 -> 3 | AA8: =$E$3+$E$6 -> 28 | AB8: =$F$3+$F$6 -> 6 | AC8: =PRODUCT(X8:AB8) -> 1512 | AD8: =AC8/$B$19 -> 1.8272479e-05 | AE8: =AD8*$A$22 -> 0.00036544958 | AF8: =AE8*$B$27 -> 0.018272479 | AG8: =AF8/$B$22 -> 0.0018272479
A9: L2 | B9: 7 | C9: 2 | D9: 2 | E9: 0 | F9: 6 | I9: 4xH3 | J9: =J8 -> 3 | K9: =K8 -> 1 | L9: =L8 -> 3 | M9: =M8 -> 28 | N9: =F18-N8 -> 42 | O9: =PRODUCT(J9:N9) -> 10584 | P9: =O9/$B$19 -> 0.00012790735 | Q9: =P9*$A$22 -> 0.0025581471 | R9: =Q9*C27 -> 0.030697765 | S9: =R9/$B$22 -> 0.0030697765 | W9: 4xH3 | X9: =$B$3+$B$6 -> 3 | Y9: =$C$3+$C$6 -> 1 | Z9: =$D$14 -> 3 | AA9: =$E$3+$E$6 -> 28 | AB9: =$F$18-$F$3-$F$6 -> 42 | AC9: =PRODUCT(X9:AB9) -> 10584 | AD9: =AC9/$B$19 -> 0.00012790735 | AE9: =AD9*$A$22 -> 0.0025581471 | AF9: =AE9*$C$27 -> 0.030697765 | AG9: =AF9/$B$22 -> 0.0030697765
A10: L3 | B10: 7 | C10: 2 | D10: 2 | E10: 2 | F10: 6 | I10: 3xH3 | J10: =J9 -> 3 | K10: =K9 -> 1 | L10: =L9 -> 3 | M10: =E18-M9 -> 24 | N10: =F18 -> 48 | O10: =PRODUCT(J10:N10) -> 10368 | P10: =O10/$B$19 -> 0.000125297 | Q10: =P10*$A$22 -> 0.00250594 | R10: =Q10*D27 -> 0.00501188 | S10: =R10/$B$22 -> 0.000501188 | W10: 3xH3 | X10: =$B$3+$B$6 -> 3 | Y10: =$C$3+$C$6 -> 1 | Z10: =$D$14 -> 3 | AA10: =$E$18-$E$3-$E$6 -> 24 | AB10: =$F$18 -> 48 | AC10: =PRODUCT(X10:AB10) -> 10368 | AD10: =AC10/$B$19 -> 0.000125297 | AE10: =AD10*$A$22 -> 0.00250594 | AF10: =AE10*D27 -> 0.00501188 | AG10: =AF10/$B$22 -> 0.000501188
A11: L4 | B11: 2 | C11: 6 | D11: 0 | E11: 0 | F11: 6 | I11: 5xH4 | J11: =B3+B7 -> 2 | K11: =C3+C7 -> 9 | L11: =D3+D7 -> 5 | M11: =E3+E7 -> 28 | N11: =F3+F7 -> 6 | O11: =PRODUCT(J11:N11) -> 15120 | P11: =O11/$B$19 -> 0.00018272479 | Q11: =P11*$A$22 -> 0.0036544958 | R11: =Q11*B28 -> 0.18272479 | S11: =R11/$B$22 -> 0.018272479 | W11: 5xH4 | X11: =$B$3+$B$7 -> 2 | Y11: =$C$3+$C$7 -> 9 | Z11: =$D$14 -> 3 | AA11: =$E$3+$E$7 -> 28 | AB11: =$F$3+$F$7 -> 6 | AC11: =PRODUCT(X11:AB11) -> 9072 | AD11: =AC11/$B$19 -> 0.00010963488 | AE11: =AD11*$A$22 -> 0.0021926975 | AF11: =AE11*B28 -> 0.10963488 | AG11: =AF11/$B$22 -> 0.010963488
A12: L5 | B12: 2 | C12: 6 | D12: 0 | E12: 4 | F12: 6 | I12: 4xH4 | J12: =J11 -> 2 | K12: =K11 -> 9 | L12: =L11 -> 5 | M12: =M11 -> 28 | N12: =F18-N11 -> 42 | O12: =PRODUCT(J12:N12) -> 105840 | P12: =O12/$B$19 -> 0.0012790735 | Q12: =P12*$A$22 -> 0.025581471 | R12: =Q12*C28 -> 0.30697765 | S12: =R12/$B$22 -> 0.030697765 | W12: 4xH4 | X12: =$B$3+$B$7 -> 2 | Y12: =$C$3+$C$7 -> 9 | Z12: =$D$14 -> 3 | AA12: =AA11 -> 28 | AB12: =$F$18-$F$3-$F$7 -> 42 | AC12: =PRODUCT(X12:AB12) -> 63504 | AD12: =AC12/$B$19 -> 0.00076744413 | AE12: =AD12*$A$22 -> 0.015348883 | AF12: =AE12*$C$28 -> 0.18418659 | AG12: =AF12/$B$22 -> 0.018418659
A13: SC | B13: 0 | C13: 4 | D13: 2 | E13: 4 | F13: 0 | I13: 3xH4 | J13: =J12 -> 2 | K13: =K12 -> 9 | L13: =L12 -> 5 | M13: =E18-M11 -> 24 | N13: =F18 -> 48 | O13: =PRODUCT(J13:N13) -> 103680 | P13: =O13/$B$19 -> 0.00125297 | Q13: =P13*$A$22 -> 0.0250594 | R13: =Q13*D28 -> 0.0501188 | S13: =R13/$B$22 -> 0.00501188 | W13: 3xH4 | X13: =$B$3+$B$7 -> 2 | Y13: =$C$3+$C$7 -> 9 | Z13: =$D$14 -> 3 | AA13: =$E$18-$E$3-$E$7 -> 24 | AB13: =$F$18 -> 48 | AC13: =PRODUCT(X13:AB13) -> 62208 | AD13: =AC13/$B$19 -> 0.000751782 | AE13: =AD13*$A$22 -> 0.01503564 | AF13: =AE13*$D$28 -> 0.03007128 | AG13: =AF13/$B$22 -> 0.003007128
A14: RS | B14: 0 | C14: 0 | D14: 3 | E14: 0 | F14: 0 | I14: 5xL1 | J14: =B3+B8 -> 4 | K14: =C3+C8 -> 9 | L14: =D3+D8 -> 7 | M14: =E3+E8 -> 34 | N14: =F3+F8 -> 5 | O14: =PRODUCT(J14:N14) -> 42840 | P14: =O14/$B$19 -> 0.00051772024 | Q14: =P14*$A$22 -> 0.010354405 | R14: =Q14*B29 -> 0.4141762 | S14: =R14/$B$22 -> 0.04141762 | W14: 5xL1 | X14: =$B$3+$B$8 -> 4 | Y14: =$C$3+$C$8 -> 9 | Z14: =$D$14 -> 3 | AA14: =$E$3+$E$8 -> 34 | AB14: =$F$3+$F$8 -> 5 | AC14: =PRODUCT(X14:AB14) -> 18360 | AD14: =AC14/$B$19 -> 0.0002218801 | AE14: =AD14*$A$22 -> 0.0044376021 | AF14: =AE14*$B$29 -> 0.17750408 | AG14: =AF14/$B$22 -> 0.017750408
A15: Collect | B15: 0 | C15: 0 | D15: 0 | E15: 0 | F15: 0 | I15: 4xL1 | J15: =J14 -> 4 | K15: =K14 -> 9 | L15: =L14 -> 7 | M15: =M14 -> 34 | N15: =F18-N14 -> 43 | O15: =PRODUCT(J15:N15) -> 368424 | P15: =O15/$B$19 -> 0.0044523941 | Q15: =P15*$A$22 -> 0.089047882 | R15: =Q15*C29 -> 0.62333517 | S15: =R15/$B$22 -> 0.062333517 | W15: 4xL1 | X15: =$B$3+$B$8 -> 4 | Y15: =$C$3+$C$8 -> 9 | Z15: =$D$14 -> 3 | AA15: =$E$3+$E$8 -> 34 | AB15: =$F$18-$F$3-$F$8 -> 43 | AC15: =PRODUCT(X15:AB15) -> 157896 | AD15: =AC15/$B$19 -> 0.0019081689 | AE15: =AD15*$A$22 -> 0.038163378 | AF15: =AE15*$C$29 -> 0.26714365 | AG15: =AF15/$B$22 -> 0.026714365
A16: Coin | B16: 0 | C16: 0 | D16: 0 | E16: 0 | F16: 0 | I16: 3xL1 | J16: =J14 -> 4 | K16: =K14 -> 9 | L16: =L14 -> 7 | M16: =E18-M14 -> 18 | N16: =F18 -> 48 | O16: =PRODUCT(J16:N16) -> 217728 | P16: =O16/$B$19 -> 0.002631237 | Q16: =P16*$A$22 -> 0.05262474 | R16: =Q16*D29 -> 0.10524948 | S16: =R16/$B$22 -> 0.010524948 | W16: 3xL1 | X16: =$B$3+$B$8 -> 4 | Y16: =$C$3+$C$8 -> 9 | Z16: =$D$14 -> 3 | AA16: =$E$18-$E$3-$E$8 -> 18 | AB16: =$F$18 -> 48 | AC16: =PRODUCT(X16:AB16) -> 93312 | AD16: =AC16/$B$19 -> 0.001127673 | AE16: =AD16*$A$22 -> 0.02255346 | AF16: =AE16*$D$29 -> 0.04510692 | AG16: =AF16/$B$22 -> 0.004510692
A17: Res1 | B17: 0 | C17: 0 | D17: 0 | E17: 0 | F17: 0 | I17: 5xL2 | J17: =B3+B9 -> 7 | K17: =C3+C9 -> 3 | L17: =D3+D9 -> 5 | M17: =E3+E9 -> 28 | N17: =F3+F9 -> 6 | O17: =PRODUCT(J17:N17) -> 17640 | P17: =O17/$B$19 -> 0.00021317892 | Q17: =P17*$A$22 -> 0.0042635785 | R17: =Q17*B30 -> 0.10658946 | S17: =R17/$B$22 -> 0.010658946 | W17: 5xL2 | X17: =$B$3+$B$9 -> 7 | Y17: =$C$3+$C$9 -> 3 | Z17: =$D$14 -> 3 | AA17: =$E$3+$E$9 -> 28 | AB17: =$F$3+$F$9 -> 6 | AC17: =PRODUCT(X17:AB17) -> 10584 | AD17: =AC17/$B$19 -> 0.00012790735 | AE17: =AD17*$A$22 -> 0.0025581471 | AF17: =AE17*B30 -> 0.063953677 | AG17: =AF17/$B$22 -> 0.0063953677
A18: Total | B18: =SUM(B3:B17) -> 32 | C18: =SUM(C3:C17) -> 37 | D18: =SUM(D3:D17) -> 28 | E18: =SUM(E3:E17) -> 52 | F18: =SUM(F3:F17) -> 48 | I18: 4xL2 | J18: =J17 -> 7 | K18: =K17 -> 3 | L18: =L17 -> 5 | M18: =M17 -> 28 | N18: =F18-N17 -> 42 | O18: =PRODUCT(J18:N18) -> 123480 | P18: =O18/$B$19 -> 0.0014922525 | Q18: =P18*$A$22 -> 0.029845049 | R18: =Q18*C30 -> 0.14922525 | S18: =R18/$B$22 -> 0.014922525 | W18: 4xL2 | X18: =$B$3+$B$9 -> 7 | Y18: =$C$3+$C$9 -> 3 | Z18: =$D$14 -> 3 | AA18: =$E$3+$E$9 -> 28 | AB18: =$F$18-$F$3-$F$9 -> 42 | AC18: =PRODUCT(X18:AB18) -> 74088 | AD18: =AC18/$B$19 -> 0.00089535148 | AE18: =AD18*$A$22 -> 0.01790703 | AF18: =AE18*$C$30 -> 0.089535148 | AG18: =AF18/$B$22 -> 0.0089535148
A19: Total Cycles | B19: =PRODUCT(B18:F18) -> 82747392 | I19: 3xL2 | J19: =J17 -> 7 | K19: =K17 -> 3 | L19: =L17 -> 5 | M19: =E18-M17 -> 24 | N19: =F18 -> 48 | O19: =PRODUCT(J19:N19) -> 120960 | P19: =O19/$B$19 -> 0.0014617983 | Q19: =P19*$A$22 -> 0.029235967 | R19: =Q19*D30 -> 0.058471933 | S19: =R19/$B$22 -> 0.0058471933 | W19: 3xL2 | X19: =$B$3+$B$9 -> 7 | Y19: =$C$3+$C$9 -> 3 | Z19: =$D$14 -> 3 | AA19: =$E$18-$E$3-$E$9 -> 24 | AB19: =$F$18 -> 48 | AC19: =PRODUCT(X19:AB19) -> 72576 | AD19: =AC19/$B$19 -> 0.000877079 | AE19: =AD19*$A$22 -> 0.01754158 | AF19: =AE19*$D$30 -> 0.03508316 | AG19: =AF19/$B$22 -> 0.003508316
I20: 5xL3 | J20: =B3+B10 -> 7 | K20: =C3+C10 -> 3 | L20: =D3+D10 -> 5 | M20: =E3+E10 -> 30 | N20: =F3+F10 -> 6 | O20: =PRODUCT(J20:N20) -> 18900 | P20: =O20/$B$19 -> 0.00022840599 | Q20: =P20*$A$22 -> 0.0045681198 | R20: =Q20*B31 -> 0.114203 | S20: =R20/$B$22 -> 0.0114203 | W20: 5xL3 | X20: =$B$3+$B$10 -> 7 | Y20: =$C$3+$C$10 -> 3 | Z20: =$D$14 -> 3 | AA20: =$E$3+$E$10 -> 30 | AB20: =$F$3+$F$10 -> 6 | AC20: =PRODUCT(X20:AB20) -> 11340 | AD20: =AC20/$B$19 -> 0.00013704359 | AE20: =AD20*$A$22 -> 0.0027408719 | AF20: =AE20*$B$31 -> 0.068521797 | AG20: =AF20/$B$22 -> 0.0068521797
A21: Total Lines | B21: Wage | I21: 4xL3 | J21: =J20 -> 7 | K21: =K20 -> 3 | L21: =L20 -> 5 | M21: =M20 -> 30 | N21: =F18-N20 -> 42 | O21: =PRODUCT(J21:N21) -> 132300 | P21: =O21/$B$19 -> 0.0015988419 | Q21: =P21*$A$22 -> 0.031976839 | R21: =Q21*C31 -> 0.15988419 | S21: =R21/$B$22 -> 0.015988419 | W21: 4xL3 | X21: =$B$3+$B$10 -> 7 | Y21: =$C$3+$C$10 -> 3 | Z21: =$D$14 -> 3 | AA21: =$E$3+$E$10 -> 30 | AB21: =$F$18-$F$3-$F$10 -> 42 | AC21: =PRODUCT(X21:AB21) -> 79380 | AD21: =AC21/$B$19 -> 0.00095930516 | AE21: =AD21*$A$22 -> 0.019186103 | AF21: =AE21*$C$31 -> 0.095930516 | AG21: =AF21/$B$22 -> 0.0095930516
A22: 20 | B22: 10 | I22: 3xL3 | J22: =J20 -> 7 | K22: =K20 -> 3 | L22: =L20 -> 5 | M22: =E18-M20 -> 22 | N22: =F18 -> 48 | O22: =PRODUCT(J22:N22) -> 110880 | P22: =O22/$B$19 -> 0.0013399818 | Q22: =P22*$A$22 -> 0.026799636 | R22: =Q22*D31 -> 0.053599272 | S22: =R22/$B$22 -> 0.0053599272 | W22: 3xL3 | X22: =$B$3+$B$10 -> 7 | Y22: =$C$3+$C$10 -> 3 | Z22: =$D$14 -> 3 | AA22: =$E$18-$E$3-$E$10 -> 22 | AB22: =$F$18 -> 48 | AC22: =PRODUCT(X22:AB22) -> 66528 | AD22: =AC22/$B$19 -> 0.00080398909 | AE22: =AD22*$A$22 -> 0.016079782 | AF22: =AE22*D31 -> 0.032159563 | AG22: =AF22/$B$22 -> 0.0032159563
I23: 5xL4 | J23: =B3+B11 -> 2 | K23: =C3+C11 -> 7 | L23: =D3+D11 -> 3 | M23: =E3+E11 -> 28 | N23: =F3+F11 -> 6 | O23: =PRODUCT(J23:N23) -> 7056 | P23: =O23/$B$19 -> 8.527157e-05 | Q23: =P23*$A$22 -> 0.0017054314 | R23: =Q23*B32 -> 0.042635785 | S23: =R23/$B$22 -> 0.0042635785 | W23: 5xL4 | X23: =$B$3+$B$11 -> 2 | Y23: =$C$3+$C$11 -> 7 | Z23: =$D$14 -> 3 | AA23: =$E$3+$E$11 -> 28 | AB23: =$F$3+$F$11 -> 6 | AC23: =PRODUCT(X23:AB23) -> 7056 | AD23: =AC23/$B$19 -> 8.527157e-05 | AE23: =AD23*$A$22 -> 0.0017054314 | AF23: =AE23*$B$32 -> 0.042635785 | AG23: =AF23/$B$22 -> 0.0042635785
A24: Symbol | B24: 5 OAK | C24: 4 OAK | D24: 3 OAK | I24: 4xL4 | J24: =J23 -> 2 | K24: =K23 -> 7 | L24: =L23 -> 3 | M24: =M23 -> 28 | N24: =F18-N23 -> 42 | O24: =PRODUCT(J24:N24) -> 49392 | P24: =O24/$B$19 -> 0.00059690099 | Q24: =P24*$A$22 -> 0.01193802 | R24: =Q24*C32 -> 0.059690099 | S24: =R24/$B$22 -> 0.0059690099 | W24: 4xL4 | X24: =$B$3+$B$11 -> 2 | Y24: =$C$3+$C$11 -> 7 | Z24: =$D$14 -> 3 | AA24: =$E$3+$E$11 -> 28 | AB24: =$F$18-$F$3-$F$11 -> 42 | AC24: =PRODUCT(X24:AB24) -> 49392 | AD24: =AC24/$B$19 -> 0.00059690099 | AE24: =AD24*$A$22 -> 0.01193802 | AF24: =AE24*$C$32 -> 0.059690099 | AG24: =AF24/$B$22 -> 0.0059690099
A25: H1 | B25: 75 | C25: 25 | D25: 2 | I25: 3xL4 | J25: =J23 -> 2 | K25: =K23 -> 7 | L25: =L23 -> 3 | M25: =E18-M23 -> 24 | N25: =F18 -> 48 | O25: =PRODUCT(J25:N25) -> 48384 | P25: =O25/$B$19 -> 0.00058471933 | Q25: =P25*$A$22 -> 0.011694387 | R25: =Q25*D32 -> 0.023388773 | S25: =R25/$B$22 -> 0.0023388773 | W25: 3xL4 | X25: =$B$3+$B$11 -> 2 | Y25: =$C$3+$C$11 -> 7 | Z25: =$D$14 -> 3 | AA25: =$E$18-$E$3-$E$11 -> 24 | AB25: =$F$18 -> 48 | AC25: =PRODUCT(X25:AB25) -> 48384 | AD25: =AC25/$B$19 -> 0.00058471933 | AE25: =AD25*$A$22 -> 0.011694387 | AF25: =AE25*$D$32 -> 0.023388773 | AG25: =AF25/$B$22 -> 0.0023388773
A26: H2 | B26: 50 | C26: 12 | D26: 2 | I26: 5xL5 | J26: =B3+B12 -> 2 | K26: =C3+C12 -> 7 | L26: =D3+D12 -> 3 | M26: =E3+E12 -> 32 | N26: =F3+F12 -> 6 | O26: =PRODUCT(J26:N26) -> 8064 | P26: =O26/$B$19 -> 9.7453222e-05 | Q26: =P26*$A$22 -> 0.0019490644 | R26: =Q26*B33 -> 0.048726611 | S26: =R26/$B$22 -> 0.0048726611 | W26: 5xL5 | X26: =$B$3+$B$12 -> 2 | Y26: =$C$3+$C$12 -> 7 | Z26: =$D$14 -> 3 | AA26: =$E$3+$E$12 -> 32 | AB26: =$F$3+$F$12 -> 6 | AC26: =PRODUCT(X26:AB26) -> 8064 | AD26: =AC26/$B$19 -> 9.7453222e-05 | AE26: =AD26*$A$22 -> 0.0019490644 | AF26: =AE26*$B$33 -> 0.048726611 | AG26: =AF26/$B$22 -> 0.0048726611
A27: H3 | B27: 50 | C27: 12 | D27: 2 | I27: 4xL5 | J27: =J26 -> 2 | K27: =K26 -> 7 | L27: =L26 -> 3 | M27: =M26 -> 32 | N27: =F18-N26 -> 42 | O27: =PRODUCT(J27:N27) -> 56448 | P27: =O27/$B$19 -> 0.00068217256 | Q27: =P27*$A$22 -> 0.013643451 | R27: =Q27*C33 -> 0.068217256 | S27: =R27/$B$22 -> 0.0068217256 | W27: 4xL5 | X27: =$B$3+$B$12 -> 2 | Y27: =$C$3+$C$12 -> 7 | Z27: =$D$14 -> 3 | AA27: =$E$3+$E$12 -> 32 | AB27: =$F$18-$F$3-$F$12 -> 42 | AC27: =PRODUCT(X27:AB27) -> 56448 | AD27: =AC27/$B$19 -> 0.00068217256 | AE27: =AD27*$A$22 -> 0.013643451 | AF27: =AE27*$C$33 -> 0.068217256 | AG27: =AF27/$B$22 -> 0.0068217256
A28: H4 | B28: 50 | C28: 12 | D28: 2 | I28: 3xL5 | J28: =J26 -> 2 | K28: =K26 -> 7 | L28: =L26 -> 3 | M28: =E18-M26 -> 20 | N28: =F18 -> 48 | O28: =PRODUCT(J28:N28) -> 40320 | P28: =O28/$B$19 -> 0.00048726611 | Q28: =P28*$A$22 -> 0.0097453222 | R28: =Q28*D33 -> 0.019490644 | S28: =R28/$B$22 -> 0.0019490644 | W28: 3xL5 | X28: =$B$3+$B$12 -> 2 | Y28: =$C$3+$C$12 -> 7 | Z28: =$D$14 -> 3 | AA28: =$E$18-E3-$E$12 -> 20 | AB28: =$F$18 -> 48 | AC28: =PRODUCT(X28:AB28) -> 40320 | AD28: =AC28/$B$19 -> 0.00048726611 | AE28: =AD28*$A$22 -> 0.0097453222 | AF28: =AE28*$D$33 -> 0.019490644 | AG28: =AF28/$B$22 -> 0.0019490644
A29: L1 | B29: 40 | C29: 7 | D29: 2 | P29: =SUM(P2:P28) -> 0.020632239 | Q29: =SUM(Q2:Q28) -> 0.41264479 | R29: =SUM(R2:R28) -> 2.9649737 | S29: =SUM(S2:S28) -> 0.29649737 | AD29: =SUM(AD2:AD28) -> 0.011944981 | AE29: =SUM(AE2:AE28) -> 0.23889961 | AF29: =SUM(AF2:AF28) -> 1.6352477 | AG29: =SUM(AG2:AG28) -> 0.16352477
A30: L2 | B30: 25 | C30: 5 | D30: 2
A31: L3 | B31: 25 | C31: 5 | D31: 2
A32: L4 | B32: 25 | C32: 5 | D32: 2 | I32: Prize SC | J32: R1 | K32: R2 | L32: R3 | M32: R4 | N32: R5 | O32: HITS | P32: Hit Rate | Q32: Total Hit Rate | R32: RTP(%) | S32: RTP(%) 1c | W32: Prize SC with RS | X32: R1 | Y32: R2 | Z32: R3 | AA32: R4 | AB32: R5 | AC32: HITS | AD32: Hit Rate | AE32: Total Hit Rate | AF32: RTP(%) | AG32: RTP(%) 1c
A33: L5 | B33: 25 | C33: 5 | D33: 2 | I33: 3xSC | J33: =$B$18 -> 32 | K33: =$C$13*3 -> 12 | L33: =$D$13*3 -> 6 | M33: =$E$13*3 -> 12 | N33: =$F$18 -> 48 | O33: =PRODUCT(J33:N33) -> 1327104 | P33: =O33/$B$19 -> 0.016038016 | Q33: =P33 -> 0.016038016 | R33: =Q33*D34 -> 0.016038016 | S33: =R33 -> 0.016038016 | W33: SC,RS,SC | X33: =$B$18 -> 32 | Y33: =$C$13*3 -> 12 | Z33: =$D$14*3 -> 9 | AA33: =$E$13*3 -> 12 | AB33: =$F$18 -> 48 | AC33: =PRODUCT(X33:AB33) -> 1990656 | AD33: =AC33/$B$19 -> 0.024057024 | AE33: =AD33 -> 0.024057024 | AF33: =AE33*$D$34 -> 0.024057024 | AG33: =AF33 -> 0.024057024
A34: SC | B34: 50 | C34: 5 | D34: 1
AG38: =AG29+AG33 -> 0.18758179
S39: =S29+S33 -> 0.31253538 | W39: Hit Both | X39: =AE29*AE33 -> 0.0057472138 | AG39: =AG38*X39 -> 0.0010780727
S40: =S39+AG29 -> 0.47606015
S41: =S40+AG33 -> 0.50011718

Sheet Step-5
A1: Symbol Set Population | B1: Symbol Set Population | C1: Symbol Set Population | D1: Symbol Set Population | E1: Symbol Set Population | F1: Symbol Set Population | I1: Prize | J1: R1 | K1: R2 | L1: R3 | M1: R4 | N1: R5 | O1: HITS | P1: Hit Rate | Q1: Total Hit Rate | R1: RTP(%) | S1: RTP(%) 1c | W1: Prize With RS | X1: R1 | Y1: R2 | Z1: R3 | AA1: R4 | AB1: R5 | AC1: HITS | AD1: Hit Rate | AE1: Total Hit Rate | AF1: RTP(%) | AG1: RTP(%) 1c
A2: Symbol | B2: BaseRS11R0 | C2: BaseRS11R1 | D2: BaseRS11R2 | E2: BaseRS11R3 | F2: BaseRS11R4 | I2: 5xH1 | J2: =B3+B4 -> 2 | K2: =C3+C4 -> 1 | L2: =D3+D4 -> 9 | M2: =E3+E4 -> 32 | N2: =F3+F4 -> 3 | O2: =PRODUCT(J2:N2) -> 1728 | P2: =O2/$B$19 -> 2.2489205e-05 | Q2: =P2*$A$22 -> 0.0004497841 | R2: =Q2*B25 -> 0.033733808 | S2: =R2/$B$22 -> 0.0033733808 | W2: 5xH1 | X2: =$B$3+$B$4 -> 2 | Y2: =$C$3+$C$4 -> 1 | Z2: =$D$14 -> 3 | AA2: =$E$3+$E$4 -> 32 | AB2: =$F$3+$F$4 -> 3 | AC2: =PRODUCT(X2:AB2) -> 576 | AD2: =AC2/$B$19 -> 7.4964017e-06 | AE2: =AD2 -> 7.4964017e-06 | AF2: =AE2*B25 -> 0.00056223013 | AG2: =AF2/$B$22 -> 5.6223013e-05
A3: WD | B3: 0 | C3: 1 | D3: 3 | E3: 28 | F3: 0 | I3: 4xH1 | J3: =J2 -> 2 | K3: =K2 -> 1 | L3: =L2 -> 9 | M3: =M2 -> 32 | N3: =F18-N2 -> 45 | O3: =PRODUCT(J3:N3) -> 25920 | P3: =O3/$B$19 -> 0.00033733808 | Q3: =P3*$A$22 -> 0.0067467616 | R3: =Q3*C25 -> 0.16866904 | S3: =R3/$B$22 -> 0.016866904 | W3: 4xH1 | X3: =$B$3+$B$4 -> 2 | Y3: =$C$3+$C$4 -> 1 | Z3: =$D$14 -> 3 | AA3: =$E$3+$E$4 -> 32 | AB3: =$F$18-$F$3-$F$4 -> 45 | AC3: =PRODUCT(X3:AB3) -> 8640 | AD3: =AC3/$B$19 -> 0.00011244603 | AE3: =AD3 -> 0.00011244603 | AF3: =AE3*C25 -> 0.0028111506 | AG3: =AF3/$B$22 -> 0.00028111506
A4: H1 | B4: 2 | C4: 0 | D4: 6 | E4: 4 | F4: 3 | I4: 3xH1 | J4: =J2 -> 2 | K4: =K2 -> 1 | L4: =L2 -> 9 | M4: =E18-M2 -> 20 | N4: 48 | O4: =PRODUCT(J4:N4) -> 17280 | P4: =O4/$B$19 -> 0.00022489205 | Q4: =P4*$A$22 -> 0.004497841 | R4: =Q4*D25 -> 0.0089956821 | S4: =R4/$B$22 -> 0.00089956821 | W4: 3xH1 | X4: =$B$3+$B$4 -> 2 | Y4: =$C$3+$C$4 -> 1 | Z4: =$D$14 -> 3 | AA4: =$E$18-$E$3-$E$4 -> 20 | AB4: =$F$18 -> 48 | AC4: =PRODUCT(X4:AB4) -> 5760 | AD4: =AC4/$B$19 -> 7.4964017e-05 | AE4: =AD4 -> 7.4964017e-05 | AF4: =AE4*D25 -> 0.00014992803 | AG4: =AF4/$B$22 -> 1.4992803e-05
